Workbook

Sheet العاصمه
A1: السنه | B1: الشهر | C1: حادث تلفيات | D1: حادث اصابات | E1: حادث وفيات | F1: مجموع عدد الحوادث | G1: السبت | H1: الا حد | I1: الاثنين | J1: الثلاثاء | K1: الا ربعاء | L1: الخميس | M1: الجمعة | N1: مجموع عدد الحوادث لجميع الأيام | O1: نهارا | P1: ليلا | Q1: مجموع عدد الحوادث حسب الوقت | R1: داخل المدينة | S1: خارج المدينة | T1: مجموع عدد الحوادث حسب مكان الحادث | U1: صغيرة | V1: جيب | W1: حافلة | X1: ونيت | Y1: نقل | Z1: وايت | AA1: اخرى | AB1: مجموع عدد السيارات المشتركة في الحوادث حسب الطراز | AC1: -18 | AD1: 18+ | AE1: 30+ | AF1: 40+ | AG1: 50+ | AH1: المجموع حسب العمر | AI1: سعودي | AJ1: اجنبي | AK1: المجموع حسب الجنسية | AL1: متزوج | AM1: اعزب | AN1: المجموع حسب الحالة الاجتماعية | AO1: متعلم | AP1: امى | AQ1: المجموع حسب الحالة التعليمية | AR1: نوع الرخصة خصوصى | AS1: نوع الرخصة عمومى | AT1: نوع الرخصة اليات | AU1: نوع الرخصة دراجة | AV1: السائق لا يحمل رخصة قيادة | AW1: المجموع | AX1: السائق لا يحمل رخصة قيادة | AY1: الرخصة سارية | AZ1: الرخصة منتهية | BA1: المجموع | BB1: تصادم مع سيارة | BC1: تصادم مع جسم ثابت | BD1: دهس مشاة | BE1: دهس حيوان | BF1: حريق | BG1: انقلاب | BH1: خروج عن الطريق | BI1: أخرى | BJ1: المجموع | BK1: توقف غير نظامى | BL1: دوران غير نظامى | BM1: تجاوز غير نظامى | BN1: عدم التقيد بالاشارة | BO1: السرعة الزائدة | BP1: السائق تحت تأثير مخدر | BQ1: اخرى | BR1: مجموع الحوادث حسب سبب الحادث | BS1: عدد المصابين | BT1: عدد المتوفين (القتلى) | BU1: سليم | BV1: مجموع الأشخاص المشمولين بالحوادث
A2: 1437 | B2: محرم | C2: 4405 | D2: 119 | E2: 55 | F2: =SUM(C2:E2) -> 4579 | G2: 650 | H2: 637 | I2: 616 | J2: 626 | K2: 705 | L2: 679 | M2: 666 | N2: =G2+H2+I2+J2+K2+L2+M2 -> 4579 | O2: 2953 | P2: 1626 | Q2: =SUM(O2:P2) -> 4579 | R2: 3214 | S2: 1365 | T2: =SUM(R2:S2) -> 4579 | U2: 3844 | V2: 1827 | W2: 310 | X2: 1796 | Y2: 399 | Z2: 208 | AA2: 41 | AB2: =SUM(U2:AA2) -> 8425 | AC2: 364 | AD2: 2179 | AE2: 3220 | AF2: 2297 | AG2: 332 | AH2: =SUM(AC2:AG2) -> 8392 | AI2: 5346 | AJ2: 3046 | AK2: =SUM(AI2:AJ2) -> 8392 | AL2: 3849 | AM2: 4543 | AN2: =SUM(AL2:AM2) -> 8392 | AO2: 8292 | AP2: 100 | AQ2: =SUM(AO2:AP2) -> 8392 | AR2: 4145 | AS2: 3416 | AT2: 232 | AU2: 384 | AV2: 215 | AW2: =+AR2+AS2+AT2+AU2+AV2 -> 8392 | AX2: =AV2 -> 215 | AY2: 7904 | AZ2: 273 | BA2: =SUM(AX2:AZ2) -> 8392 | BB2: 4229 | BC2: 79 | BD2: 37 | BE2: 3 | BF2: 0 | BG2: 43 | BH2: 113 | BI2: 75 | BJ2: =SUM(BB2:BI2) -> 4579 | BK2: 1166 | BL2: 370 | BM2: 460 | BN2: 1135 | BO2: 1416 | BP2: 0 | BQ2: 32 | BR2: =SUM(BK2:BQ2) -> 4579 | BS2: 237 | BT2: 82 | BU2: 8752 | BV2: =SUM(BS2:BU2) -> 9071
B3: صفر | C3: 4473 | D3: 111 | E3: 60 | F3: =SUM(C3:E3) -> 4644 | G3: 648 | H3: 647 | I3: 655 | J3: 655 | K3: 659 | L3: 692 | M3: 688 | N3: =G3+H3+I3+J3+K3+L3+M3 -> 4644 | O3: 2572 | P3: 2072 | Q3: =SUM(O3:P3) -> 4644 | R3: 3009 | S3: 1635 | T3: =SUM(R3:S3) -> 4644 | U3: 3424 | V3: 1444 | W3: 298 | X3: 2583 | Y3: 598 | Z3: 311 | AA3: 142 | AB3: =SUM(U3:AA3) -> 8800 | AC3: 320 | AD3: 2854 | AE3: 2227 | AF3: 2059 | AG3: 1191 | AH3: =SUM(AC3:AG3) -> 8651 | AI3: 5943 | AJ3: 2708 | AK3: =SUM(AI3:AJ3) -> 8651 | AL3: 5831 | AM3: 2820 | AN3: =SUM(AL3:AM3) -> 8651 | AO3: 8551 | AP3: 100 | AQ3: =SUM(AO3:AP3) -> 8651 | AR3: 4251 | AS3: 3580 | AT3: 283 | AU3: 295 | AV3: 242 | AW3: =SUM(AR3:AV3) -> 8651 | AX3: =AV3 -> 242 | AY3: 7975 | AZ3: 434 | BA3: =SUM(AX3:AZ3) -> 8651 | BB3: 4197 | BC3: 161 | BD3: 48 | BE3: 2 | BF3: 2 | BG3: 40 | BH3: 117 | BI3: 77 | BJ3: =SUM(BB3:BI3) -> 4644 | BK3: 775 | BL3: 852 | BM3: 314 | BN3: 1178 | BO3: 1402 | BP3: 0 | BQ3: 123 | BR3: =SUM(BK3:BQ3) -> 4644 | BS3: 295 | BT3: 82 | BU3: 8665 | BV3: =SUM(BS3:BU3) -> 9042
B4: ربيع أول | C4: 4628 | D4: 96 | E4: 64 | F4: =SUM(C4:E4) -> 4788 | G4: 838 | H4: 672 | I4: 632 | J4: 614 | K4: 659 | L4: 672 | M4: 701 | N4: =G4+H4+I4+J4+K4+L4+M4 -> 4788 | O4: 3019 | P4: 1769 | Q4: =SUM(O4:P4) -> 4788 | R4: 3499 | S4: 1289 | T4: =SUM(R4:S4) -> 4788 | U4: 3694 | V4: 1387 | W4: 224 | X4: 3001 | Y4: 442 | Z4: 138 | AA4: 131 | AB4: =SUM(U4:AA4) -> 9017 | AC4: 299 | AD4: 3004 | AE4: 2893 | AF4: 1755 | AG4: 995 | AH4: =SUM(AC4:AG4) -> 8946 | AI4: 6402 | AJ4: 2544 | AK4: =SUM(AI4:AJ4) -> 8946 | AL4: 4643 | AM4: 4303 | AN4: =SUM(AL4:AM4) -> 8946 | AO4: 8846 | AP4: 100 | AQ4: =SUM(AO4:AP4) -> 8946 | AR4: 6358 | AS4: 2106 | AT4: 118 | AU4: 91 | AV4: 273 | AW4: =SUM(AR4:AV4) -> 8946 | AX4: =AV4 -> 273 | AY4: 8074 | AZ4: 599 | BA4: =SUM(AX4:AZ4) -> 8946 | BB4: 4204 | BC4: 88 | BD4: 27 | BE4: 4 | BF4: 0 | BG4: 71 | BH4: 203 | BI4: 191 | BJ4: =SUM(BB4:BI4) -> 4788 | BK4: 211 | BL4: 968 | BM4: 107 | BN4: 1436 | BO4: 1163 | BP4: 0 | BQ4: 903 | BR4: =SUM(BK4:BQ4) -> 4788 | BS4: 256 | BT4: 82 | BU4: 8963 | BV4: =SUM(BS4:BU4) -> 9301
B5: ربيع ثانى | C5: 4647 | D5: 111 | E5: 83 | F5: =SUM(C5:E5) -> 4841 | G5: 628 | H5: 652 | I5: 778 | J5: 784 | K5: 648 | L5: 692 | M5: 659 | N5: =G5+H5+I5+J5+K5+L5+M5 -> 4841 | O5: 3153 | P5: 1688 | Q5: =SUM(O5:P5) -> 4841 | R5: 3517 | S5: 1324 | T5: =SUM(R5:S5) -> 4841 | U5: 3305 | V5: 1694 | W5: 132 | X5: 2801 | Y5: 524 | Z5: 76 | AA5: 56 | AB5: =SUM(U5:AA5) -> 8588 | AC5: 290 | AD5: 3345 | AE5: 2694 | AF5: 1543 | AG5: 592 | AH5: =SUM(AC5:AG5) -> 8464 | AI5: 5703 | AJ5: 2761 | AK5: =SUM(AI5:AJ5) -> 8464 | AL5: 4804 | AM5: 3660 | AN5: =SUM(AL5:AM5) -> 8464 | AO5: 8314 | AP5: 150 | AQ5: =SUM(AO5:AP5) -> 8464 | AR5: 5787 | AS5: 2256 | AT5: 159 | AU5: 41 | AV5: 221 | AW5: =SUM(AR5:AV5) -> 8464 | AX5: =AV5 -> 221 | AY5: 7687 | AZ5: 556 | BA5: =SUM(AX5:AZ5) -> 8464 | BB5: 4526 | BC5: 27 | BD5: 50 | BE5: 0 | BF5: 0 | BG5: 37 | BH5: 167 | BI5: 34 | BJ5: =SUM(BB5:BI5) -> 4841 | BK5: 748 | BL5: 988 | BM5: 324 | BN5: 101 | BO5: 794 | BP5: 0 | BQ5: 1886 | BR5: =SUM(BK5:BQ5) -> 4841 | BS5: 314 | BT5: 95 | BU5: 8555 | BV5: =SUM(BS5:BU5) -> 8964
B6: جمادى أول | C6: 4419 | D6: 81 | E6: 52 | F6: =SUM(C6:E6) -> 4552 | G6: 641 | H6: 634 | I6: 639 | J6: 640 | K6: 636 | L6: 680 | M6: 682 | N6: =G6+H6+I6+J6+K6+L6+M6 -> 4552 | O6: 2379 | P6: 2173 | Q6: =SUM(O6:P6) -> 4552 | R6: 2378 | S6: 2174 | T6: =SUM(R6:S6) -> 4552 | U6: 3526 | V6: 2399 | W6: 129 | X6: 1826 | Y6: 314 | Z6: 177 | AA6: 43 | AB6: =SUM(U6:AA6) -> 8414 | AC6: 300 | AD6: 2152 | AE6: 3224 | AF6: 2429 | AG6: 309 | AH6: =SUM(AC6:AG6) -> 8414 | AI6: 5169 | AJ6: 3245 | AK6: =SUM(AI6:AJ6) -> 8414 | AL6: 5300 | AM6: 3114 | AN6: =SUM(AL6:AM6) -> 8414 | AO6: 8200 | AP6: 214 | AQ6: =SUM(AO6:AP6) -> 8414 | AR6: 4407 | AS6: 2940 | AT6: 181 | AU6: 670 | AV6: 216 | AW6: =SUM(AR6:AV6) -> 8414 | AX6: =AV6 -> 216 | AY6: 7569 | AZ6: 629 | BA6: =SUM(AX6:AZ6) -> 8414 | BB6: 4445 | BC6: 12 | BD6: 40 | BE6: 1 | BF6: 1 | BG6: 26 | BH6: 8 | BI6: 19 | BJ6: =SUM(BB6:BI6) -> 4552 | BK6: 1411 | BL6: 1368 | BM6: 615 | BN6: 270 | BO6: 676 | BP6: 0 | BQ6: 212 | BR6: =SUM(BK6:BQ6) -> 4552 | BS6: 191 | BT6: 67 | BU6: 8263 | BV6: =SUM(BS6:BU6) -> 8521
B7: جمادى ثانى | C7: 4325 | D7: 112 | E7: 54 | F7: =SUM(C7:E7) -> 4491 | G7: 701 | H7: 637 | I7: 611 | J7: 608 | K7: 631 | L7: 666 | M7: 637 | N7: =G7+H7+I7+J7+K7+L7+M7 -> 4491 | O7: 3090 | P7: 1401 | Q7: =SUM(O7:P7) -> 4491 | R7: 3085 | S7: 1406 | T7: =SUM(R7:S7) -> 4491 | U7: 4159 | V7: 1286 | W7: 83 | X7: 2641 | Y7: 606 | Z7: 37 | AA7: 79 | AB7: =SUM(U7:AA7) -> 8891 | AC7: 101 | AD7: 3655 | AE7: 2687 | AF7: 1664 | AG7: 739 | AH7: =SUM(AC7:AG7) -> 8846 | AI7: 5735 | AJ7: 3111 | AK7: =SUM(AI7:AJ7) -> 8846 | AL7: 5006 | AM7: 3840 | AN7: =SUM(AL7:AM7) -> 8846 | AO7: 8696 | AP7: 150 | AQ7: =SUM(AO7:AP7) -> 8846 | AR7: 6124 | AS7: 2498 | AT7: 0 | AU7: 43 | AV7: 181 | AW7: =SUM(AR7:AV7) -> 8846 | AX7: =AV7 -> 181 | AY7: 8328 | AZ7: 337 | BA7: =SUM(AX7:AZ7) -> 8846 | BB7: 4227 | BC7: 26 | BD7: 42 | BE7: 2 | BF7: 1 | BG7: 56 | BH7: 71 | BI7: 66 | BJ7: =SUM(BB7:BI7) -> 4491 | BK7: 156 | BL7: 798 | BM7: 101 | BN7: 117 | BO7: 468 | BP7: 0 | BQ7: 2851 | BR7: =SUM(BK7:BQ7) -> 4491 | BS7: 243 | BT7: 69 | BU7: 8871 | BV7: =SUM(BS7:BU7) -> 9183
B8: رجب | C8: 4410 | D8: 97 | E8: 56 | F8: =SUM(C8:E8) -> 4563 | G8: 732 | H8: 652 | I8: 612 | J8: 617 | K8: 615 | L8: 628 | M8: 707 | N8: =G8+H8+I8+J8+K8+L8+M8 -> 4563 | O8: 2842 | P8: 1721 | Q8: =SUM(O8:P8) -> 4563 | R8: 3070 | S8: 1493 | T8: =SUM(R8:S8) -> 4563 | U8: 4156 | V8: 1199 | W8: 59 | X8: 3071 | Y8: 314 | Z8: 19 | AA8: 64 | AB8: =SUM(U8:AA8) -> 8882 | AC8: 97 | AD8: 3428 | AE8: 2819 | AF8: 1672 | AG8: 814 | AH8: =SUM(AC8:AG8) -> 8830 | AI8: 6409 | AJ8: 2421 | AK8: =SUM(AI8:AJ8) -> 8830 | AL8: 6314 | AM8: 2516 | AN8: =SUM(AL8:AM8) -> 8830 | AO8: 8730 | AP8: 100 | AQ8: =SUM(AO8:AP8) -> 8830 | AR8: 6383 | AS8: 2185 | AT8: 0 | AU8: 55 | AV8: 207 | AW8: =SUM(AR8:AV8) -> 8830 | AX8: =AV8 -> 207 | AY8: 7834 | AZ8: 789 | BA8: =SUM(AX8:AZ8) -> 8830 | BB8: 4212 | BC8: 80 | BD8: 41 | BE8: 1 | BF8: 0 | BG8: 31 | BH8: 112 | BI8: 86 | BJ8: =SUM(BB8:BI8) -> 4563 | BK8: 289 | BL8: 340 | BM8: 61 | BN8: 346 | BO8: 818 | BP8: 0 | BQ8: 2709 | BR8: =SUM(BK8:BQ8) -> 4563 | BS8: 238 | BT8: 71 | BU8: 8779 | BV8: =SUM(BS8:BU8) -> 9088
B9: شعبان | C9: 4591 | D9: 85 | E9: 53 | F9: =SUM(C9:E9) -> 4729 | G9: 801 | H9: 714 | I9: 652 | J9: 604 | K9: 629 | L9: 693 | M9: 636 | N9: =G9+H9+I9+J9+K9+L9+M9 -> 4729 | O9: 2785 | P9: 1944 | Q9: =SUM(O9:P9) -> 4729 | R9: 3202 | S9: 1527 | T9: =SUM(R9:S9) -> 4729 | U9: 4469 | V9: 1367 | W9: 73 | X9: 2711 | Y9: 488 | Z9: 26 | AA9: 69 | AB9: =SUM(U9:AA9) -> 9203 | AC9: 113 | AD9: 3619 | AE9: 3268 | AF9: 1320 | AG9: 804 | AH9: =SUM(AC9:AG9) -> 9124 | AI9: 7225 | AJ9: 1899 | AK9: =SUM(AI9:AJ9) -> 9124 | AL9: 4511 | AM9: 4613 | AN9: =SUM(AL9:AM9) -> 9124 | AO9: 9024 | AP9: 100 | AQ9: =SUM(AO9:AP9) -> 9124 | AR9: 6576 | AS9: 2301 | AT9: 0 | AU9: 69 | AV9: 178 | AW9: =SUM(AR9:AV9) -> 9124 | AX9: =AV9 -> 178 | AY9: 8339 | AZ9: 607 | BA9: =SUM(AX9:AZ9) -> 9124 | BB9: 4384 | BC9: 97 | BD9: 24 | BE9: 1 | BF9: 0 | BG9: 37 | BH9: 107 | BI9: 79 | BJ9: =SUM(BB9:BI9) -> 4729 | BK9: 106 | BL9: 279 | BM9: 71 | BN9: 217 | BO9: 987 | BP9: 0 | BQ9: 3069 | BR9: =SUM(BK9:BQ9) -> 4729 | BS9: 242 | BT9: 65 | BU9: 9024 | BV9: =SUM(BS9:BU9) -> 9331
B10: رمضان | C10: 4712 | D10: 113 | E10: 82 | F10: =SUM(C10:E10) -> 4907 | G10: 647 | H10: 634 | I10: 826 | J10: 810 | K10: 624 | L10: 713 | M10: 653 | N10: =G10+H10+I10+J10+K10+L10+M10 -> 4907 | O10: 1914 | P10: 2993 | Q10: =SUM(O10:P10) -> 4907 | R10: 3452 | S10: 1455 | T10: =SUM(R10:S10) -> 4907 | U10: 4972 | V10: 1386 | W10: 72 | X10: 2865 | Y10: 520 | Z10: 32 | AA10: 85 | AB10: =SUM(U10:AA10) -> 9932 | AC10: 338 | AD10: 2854 | AE10: 3469 | AF10: 2585 | AG10: 686 | AH10: =SUM(AC10:AG10) -> 9932 | AI10: 7100 | AJ10: 2832 | AK10: =SUM(AI10:AJ10) -> 9932 | AL10: 6107 | AM10: 3825 | AN10: =SUM(AL10:AM10) -> 9932 | AO10: 9757 | AP10: 175 | AQ10: =SUM(AO10:AP10) -> 9932 | AR10: 5110 | AS10: 3909 | AT10: 0 | AU10: 558 | AV10: 355 | AW10: =SUM(AR10:AV10) -> 9932 | AX10: =AV10 -> 355 | AY10: 9081 | AZ10: 496 | BA10: =SUM(AX10:AZ10) -> 9932 | BB10: 4667 | BC10: 61 | BD10: 68 | BE10: 1 | BF10: 0 | BG10: 35 | BH10: 9 | BI10: 66 | BJ10: =SUM(BB10:BI10) -> 4907 | BK10: 918 | BL10: 1000 | BM10: 1286 | BN10: 387 | BO10: 913 | BP10: 0 | BQ10: 403 | BR10: =SUM(BK10:BQ10) -> 4907 | BS10: 351 | BT10: 134 | BU10: 11045 | BV10: =SUM(BS10:BU10) -> 11530
B11: شوال | C11: 4520 | D11: 72 | E11: 44 | F11: =SUM(C11:E11) -> 4636 | G11: 636 | H11: 589 | I11: 690 | J11: 588 | K11: 704 | L11: 722 | M11: 707 | N11: =G11+H11+I11+J11+K11+L11+M11 -> 4636 | O11: 3147 | P11: 1489 | Q11: =SUM(O11:P11) -> 4636 | R11: 2850 | S11: 1786 | T11: =SUM(R11:S11) -> 4636 | U11: 4749 | V11: 1660 | W11: 347 | X11: 1761 | Y11: 395 | Z11: 222 | AA11: 138 | AB11: =SUM(U11:AA11) -> 9272 | AC11: 243 | AD11: 3795 | AE11: 2985 | AF11: 1541 | AG11: 708 | AH11: =SUM(AC11:AG11) -> 9272 | AI11: 6498 | AJ11: 2774 | AK11: =SUM(AI11:AJ11) -> 9272 | AL11: 4521 | AM11: 4751 | AN11: =SUM(AL11:AM11) -> 9272 | AO11: 9183 | AP11: 89 | AQ11: =SUM(AO11:AP11) -> 9272 | AR11: 6865 | AS11: 2102 | AT11: 0 | AU11: 42 | AV11: 263 | AW11: =SUM(AR11:AV11) -> 9272 | AX11: =AV11 -> 263 | AY11: 8448 | AZ11: 561 | BA11: =SUM(AX11:AZ11) -> 9272 | BB11: 3985 | BC11: 46 | BD11: 37 | BE11: 1 | BF11: 0 | BG11: 68 | BH11: 167 | BI11: 332 | BJ11: =SUM(BB11:BI11) -> 4636 | BK11: 105 | BL11: 295 | BM11: 95 | BN11: 246 | BO11: 1245 | BP11: 0 | BQ11: 2650 | BR11: =SUM(BK11:BQ11) -> 4636 | BS11: 291 | BT11: 86 | BU11: 9048 | BV11: =SUM(BS11:BU11) -> 9425
B12: ذى القعدة | C12: 4695 | D12: 70 | E12: 62 | F12: =SUM(C12:E12) -> 4827 | G12: 704 | H12: 681 | I12: 664 | J12: 689 | K12: 674 | L12: 714 | M12: 701 | N12: =G12+H12+I12+J12+K12+L12+M12 -> 4827 | O12: 2923 | P12: 1904 | Q12: =SUM(O12:P12) -> 4827 | R12: 3461 | S12: 1366 | T12: =SUM(R12:S12) -> 4827 | U12: 4787 | V12: 1321 | W12: 106 | X12: 2711 | Y12: 405 | Z12: 47 | AA12: 94 | AB12: =SUM(U12:AA12) -> 9471 | AC12: 83 | AD12: 3755 | AE12: 3102 | AF12: 1822 | AG12: 689 | AH12: =SUM(AC12:AG12) -> 9451 | AI12: 7489 | AJ12: 1962 | AK12: =SUM(AI12:AJ12) -> 9451 | AL12: 2511 | AM12: 6940 | AN12: =SUM(AL12:AM12) -> 9451 | AO12: 9301 | AP12: 150 | AQ12: =SUM(AO12:AP12) -> 9451 | AR12: 7347 | AS12: 1844 | AT12: 0 | AU12: 61 | AV12: 199 | AW12: =SUM(AR12:AV12) -> 9451 | AX12: =AV12 -> 199 | AY12: 9011 | AZ12: 241 | BA12: =SUM(AX12:AZ12) -> 9451 | BB12: 4545 | BC12: 58 | BD12: 29 | BE12: 1 | BF12: 0 | BG12: 37 | BH12: 119 | BI12: 38 | BJ12: =SUM(BB12:BI12) -> 4827 | BK12: 281 | BL12: 317 | BM12: 106 | BN12: 319 | BO12: 641 | BP12: 0 | BQ12: 3163 | BR12: =SUM(BK12:BQ12) -> 4827 | BS12: 194 | BT12: 71 | BU12: 9341 | BV12: =SUM(BS12:BU12) -> 9606
B13: ذى الحجة | C13: 4744 | D13: 148 | E13: 62 | F13: =SUM(C13:E13) -> 4954 | G13: 731 | H13: 674 | I13: 699 | J13: 704 | K13: 673 | L13: 724 | M13: 749 | N13: =G13+H13+I13+J13+K13+L13+M13 -> 4954 | O13: 2847 | P13: 2107 | Q13: =SUM(O13:P13) -> 4954 | R13: 3493 | S13: 1461 | T13: =SUM(R13:S13) -> 4954 | U13: 4531 | V13: 1322 | W13: 197 | X13: 3018 | Y13: 391 | Z13: 101 | AA13: 92 | AB13: =SUM(U13:AA13) -> 9652 | AC13: 91 | AD13: 4022 | AE13: 3457 | AF13: 1186 | AG13: 847 | AH13: =SUM(AC13:AG13) -> 9603 | AI13: 5912 | AJ13: 3691 | AK13: =SUM(AI13:AJ13) -> 9603 | AL13: 5012 | AM13: 4591 | AN13: =SUM(AL13:AM13) -> 9603 | AO13: 9403 | AP13: 200 | AQ13: =SUM(AO13:AP13) -> 9603 | AR13: 7974 | AS13: 1267 | AT13: 0 | AU13: 51 | AV13: 311 | AW13: =SUM(AR13:AV13) -> 9603 | AX13: =AV13 -> 311 | AY13: 9088 | AZ13: 204 | BA13: =SUM(AX13:AZ13) -> 9603 | BB13: 4583 | BC13: 57 | BD13: 104 | BE13: 3 | BF13: 0 | BG13: 35 | BH13: 68 | BI13: 104 | BJ13: =SUM(BB13:BI13) -> 4954 | BK13: 191 | BL13: 501 | BM13: 87 | BN13: 294 | BO13: 713 | BP13: 0 | BQ13: 3168 | BR13: =SUM(BK13:BQ13) -> 4954 | BS13: 262 | BT13: 65 | BU13: 9531 | BV13: =SUM(BS13:BU13) -> 9858
B14: المجموع | C14: =SUM(C2:C13) -> 54569 | D14: =SUM(D2:D13) -> 1215 | E14: =SUM(E2:E13) -> 727 | F14: =SUM(F2:F13) -> 56511 | G14: =SUM(G2:G13) -> 8357 | H14: =SUM(H2:H13) -> 7823 | I14: =SUM(I2:I13) -> 8074 | J14: =SUM(J2:J13) -> 7939 | ... M14: =SUM(M2:M13) -> 8186 | N14: =G14+H14+I14+J14+K14+L14+M14 -> 56511 | O14: =SUM(O2:O13) -> 33624 | P14: =SUM(P2:P13) -> 22887 | Q14: =SUM(Q2:Q13) -> 56511 | R14: =SUM(R2:R13) -> 38230 | S14: =SUM(S2:S13) -> 18281 | T14: =SUM(T2:T13) -> 56511 | U14: =SUM(U2:U13) -> 49616 | V14: =SUM(V2:V13) -> 18292 | ... BV14: =SUM(BV2:BV13) -> 112920
A15: 1438 | B15: محرم | C15: 883 | D15: 204 | E15: 37 | F15: =SUM(C15:E15) -> 1124 | G15: 165 | H15: 179 | I15: 161 | J15: 147 | K15: 176 | L15: 130 | M15: 166 | N15: =G15+H15+I15+J15+K15+L15+M15 -> 1124 | O15: 619 | P15: 505 | Q15: =SUM(O15:P15) -> 1124 | R15: 504 | S15: 620 | T15: =SUM(R15:S15) -> 1124 | U15: 822 | V15: 244 | W15: 0 | X15: 290 | Y15: 134 | Z15: 39 | AA15: 26 | AB15: =SUM(U15:AA15) -> 1555 | AC15: 193 | AD15: 535 | AE15: 472 | AF15: 218 | AG15: 137 | AH15: =SUM(AC15:AG15) -> 1555 | AI15: 1069 | AJ15: 486 | AK15: =SUM(AI15:AJ15) -> 1555 | AL15: 1148 | AM15: 407 | AN15: =SUM(AL15:AM15) -> 1555 | AO15: 1442 | AP15: 113 | AQ15: =SUM(AO15:AP15) -> 1555 | AR15: 1250 | AS15: 186 | AT15: 0 | AU15: 0 | AV15: 119 | AW15: =SUM(AR15:AV15) -> 1555 | AX15: =AV15 -> 119 | AY15: 1385 | AZ15: 51 | BA15: =SUM(AX15:AZ15) -> 1555 | BB15: 609 | BC15: 108 | BD15: 35 | BE15: 24 | BF15: 1 | BG15: 184 | BH15: 138 | BI15: 25 | BJ15: =SUM(BB15:BI15) -> 1124 | BK15: 15 | BL15: 12 | BM15: 54 | BN15: 5 | BO15: 124 | BP15: 1 | BQ15: 913 | BR15: =SUM(BK15:BQ15) -> 1124 | BS15: 326 | BT15: 45 | BU15: 1420 | BV15: =SUM(BS15:BU15) -> 1791
B16: صفر | C16: 939 | D16: 193 | E16: 34 | F16: =SUM(C16:E16) -> 1166 | G16: 152 | H16: 154 | I16: 173 | J16: 151 | K16: 201 | L16: 177 | M16: 158 | N16: =G16+H16+I16+J16+K16+L16+M16 -> 1166 | O16: 655 | P16: 511 | Q16: =SUM(O16:P16) -> 1166 | R16: 471 | S16: 695 | T16: =SUM(R16:S16) -> 1166 | U16: 835 | V16: 224 | W16: 6 | X16: 302 | Y16: 120 | Z16: 36 | AA16: 32 | AB16: =SUM(U16:AA16) -> 1555 | AC16: 217 | AD16: 517 | AE16: 392 | AF16: 258 | AG16: 171 | AH16: =SUM(AC16:AG16) -> 1555 | AI16: 1070 | AJ16: 485 | AK16: =SUM(AI16:AJ16) -> 1555 | AL16: 1017 | AM16: 538 | AN16: =SUM(AL16:AM16) -> 1555 | AO16: 1307 | AP16: 248 | AQ16: =SUM(AO16:AP16) -> 1555 | AR16: 1241 | AS16: 208 | AT16: 6 | AU16: 0 | AV16: 100 | AW16: =SUM(AR16:AV16) -> 1555 | AX16: =AV16 -> 100 | AY16: 1365 | AZ16: 90 | BA16: =SUM(AX16:AZ16) -> 1555 | BB16: 611 | BC16: 187 | BD16: 46 | BE16: 22 | BF16: 1 | BG16: 160 | BH16: 118 | BI16: 21 | BJ16: =SUM(BB16:BI16) -> 1166 | BK16: 21 | BL16: 28 | BM16: 34 | BN16: 5 | BO16: 244 | BP16: 0 | BQ16: 834 | BR16: =SUM(BK16:BQ16) -> 1166 | BS16: 272 | BT16: 42 | BU16: 1352 | BV16: =SUM(BS16:BU16) -> 1666
B17: ربيع أول | C17: 1061 | D17: 264 | E17: 40 | F17: =SUM(C17:E17) -> 1365 | G17: 193 | H17: 179 | I17: 187 | J17: 203 | K17: 243 | L17: 172 | M17: 188 | N17: =G17+H17+I17+J17+K17+L17+M17 -> 1365 | O17: 795 | P17: 570 | Q17: =SUM(O17:P17) -> 1365 | R17: 633 | S17: 732 | T17: =SUM(R17:S17) -> 1365 | U17: 1137 | V17: 246 | W17: 4 | X17: 361 | Y17: 124 | Z17: 36 | AA17: 35 | AB17: =SUM(U17:AA17) -> 1943 | AC17: 267 | AD17: 557 | AE17: 602 | AF17: 305 | AG17: 212 | AH17: =SUM(AC17:AG17) -> 1943 | AI17: 1421 | AJ17: 522 | AK17: =SUM(AI17:AJ17) -> 1943 | AL17: 1426 | AM17: 517 | AN17: =SUM(AL17:AM17) -> 1943 | AO17: 1911 | AP17: 32 | AQ17: =SUM(AO17:AP17) -> 1943 | AR17: 1578 | AS17: 249 | AT17: 2 | AU17: 5 | AV17: 109 | AW17: =SUM(AR17:AV17) -> 1943 | AX17: =AV17 -> 109 | AY17: 1664 | AZ17: 170 | BA17: =SUM(AX17:AZ17) -> 1943 | BB17: 777 | BC17: 241 | BD17: 46 | BE17: 17 | BF17: 0 | BG17: 146 | BH17: 135 | BI17: 3 | BJ17: =SUM(BB17:BI17) -> 1365 | BK17: 15 | BL17: 56 | BM17: 54 | BN17: 10 | BO17: 287 | BP17: 0 | BQ17: 943 | BR17: =SUM(BK17:BQ17) -> 1365 | BS17: 462 | BT17: 52 | BU17: 1676 | BV17: =SUM(BS17:BU17) -> 2190
B18: ربيع ثانى | C18: 1148 | D18: 287 | E18: 34 | F18: =SUM(C18:E18) -> 1469 | G18: 172 | H18: 227 | I18: 193 | J18: 195 | K18: 213 | L18: 266 | M18: 203 | N18: =G18+H18+I18+J18+K18+L18+M18 -> 1469 | O18: 800 | P18: 669 | Q18: =SUM(O18:P18) -> 1469 | R18: 819 | S18: 650 | T18: =SUM(R18:S18) -> 1469 | U18: 1511 | V18: 321 | W18: 8 | X18: 421 | Y18: 136 | Z18: 31 | AA18: 11 | AB18: =SUM(U18:AA18) -> 2439 | AC18: 352 | AD18: 721 | AE18: 798 | AF18: 425 | AG18: 143 | AH18: =SUM(AC18:AG18) -> 2439 | AI18: 1696 | AJ18: 743 | AK18: =SUM(AI18:AJ18) -> 2439 | AL18: 1814 | AM18: 625 | AN18: =SUM(AL18:AM18) -> 2439 | AO18: 2405 | AP18: 34 | AQ18: =SUM(AO18:AP18) -> 2439 | AR18: 1843 | AS18: 426 | AT18: 2 | AU18: 0 | AV18: 168 | AW18: =SUM(AR18:AV18) -> 2439 | AX18: =AV18 -> 168 | AY18: 1982 | AZ18: 289 | BA18: =SUM(AX18:AZ18) -> 2439 | BB18: 1054 | BC18: 194 | BD18: 37 | BE18: 27 | BF18: 0 | BG18: 124 | BH18: 27 | BI18: 6 | BJ18: =SUM(BB18:BI18) -> 1469 | BK18: 11 | BL18: 18 | BM18: 45 | BN18: 0 | BO18: 219 | BP18: 0 | BQ18: 1176 | BR18: =SUM(BK18:BQ18) -> 1469 | BS18: 420 | BT18: 38 | BU18: 1363 | BV18: =SUM(BS18:BU18) -> 1821
B19: جمادى أول | C19: 1111 | D19: 274 | E19: 26 | F19: =SUM(C19:E19) -> 1411 | G19: 219 | H19: 191 | I19: 168 | J19: 191 | K19: 215 | L19: 187 | M19: 240 | N19: =G19+H19+I19+J19+K19+L19+M19 -> 1411 | O19: 859 | P19: 552 | Q19: =SUM(O19:P19) -> 1411 | R19: 707 | S19: 704 | T19: =SUM(R19:S19) -> 1411 | U19: 1312 | V19: 314 | W19: 19 | X19: 407 | Y19: 161 | Z19: 20 | AA19: 21 | AB19: =SUM(U19:AA19) -> 2254 | AC19: 281 | AD19: 681 | AE19: 749 | AF19: 357 | AG19: 186 | AH19: =SUM(AC19:AG19) -> 2254 | AI19: 1563 | AJ19: 691 | AK19: =SUM(AI19:AJ19) -> 2254 | AL19: 1657 | AM19: 597 | AN19: =SUM(AL19:AM19) -> 2254 | AO19: 2222 | AP19: 32 | AQ19: =SUM(AO19:AP19) -> 2254 | AR19: 1673 | AS19: 373 | AT19: 7 | AU19: 1 | AV19: 200 | AW19: =SUM(AR19:AV19) -> 2254 | AX19: =AV19 -> 200 | AY19: 1769 | AZ19: 285 | BA19: =SUM(AX19:AZ19) -> 2254 | BB19: 1010 | BC19: 189 | BD19: 40 | BE19: 13 | BF19: 3 | BG19: 114 | BH19: 37 | BI19: 5 | BJ19: =SUM(BB19:BI19) -> 1411 | BK19: 8 | BL19: 12 | BM19: 45 | BN19: 0 | BO19: 184 | BP19: 0 | BQ19: 1162 | BR19: =SUM(BK19:BQ19) -> 1411 | BS19: 415 | BT19: 33 | BU19: 1802 | BV19: =SUM(BS19:BU19) -> 2250
B20: جمادى ثانى | C20: 1143 | D20: 247 | E20: 28 | F20: =SUM(C20:E20) -> 1418 | G20: 203 | H20: 199 | I20: 206 | J20: 219 | K20: 203 | L20: 188 | M20: 200 | N20: =G20+H20+I20+J20+K20+L20+M20 -> 1418 | O20: 860 | P20: 558 | Q20: =SUM(O20:P20) -> 1418 | R20: 718 | S20: 700 | T20: =SUM(R20:S20) -> 1418 | U20: 1181 | V20: 340 | W20: 6 | X20: 418 | Y20: 303 | Z20: 24 | AA20: 37 | AB20: =SUM(U20:AA20) -> 2309 | AC20: 261 | AD20: 808 | AE20: 757 | AF20: 328 | AG20: 155 | AH20: =SUM(AC20:AG20) -> 2309 | AI20: 1712 | AJ20: 597 | AK20: =SUM(AI20:AJ20) -> 2309 | AL20: 1809 | AM20: 500 | AN20: =SUM(AL20:AM20) -> 2309 | AO20: 2287 | AP20: 22 | AQ20: =SUM(AO20:AP20) -> 2309 | AR20: 1658 | AS20: 507 | AT20: 3 | AU20: 0 | AV20: 141 | AW20: =SUM(AR20:AV20) -> 2309 | AX20: =AV20 -> 141 | AY20: 1922 | AZ20: 246 | BA20: =SUM(AX20:AZ20) -> 2309 | BB20: 993 | BC20: 203 | BD20: 33 | BE20: 33 | BF20: 2 | BG20: 115 | BH20: 23 | BI20: 16 | BJ20: =SUM(BB20:BI20) -> 1418 | BK20: 32 | BL20: 61 | BM20: 89 | BN20: 10 | BO20: 160 | BP20: 0 | BQ20: 1066 | BR20: =SUM(BK20:BQ20) -> 1418 | BS20: 386 | BT20: 29 | BU20: 2223 | BV20: =SUM(BS20:BU20) -> 2638
B21: رجب | C21: 1084 | D21: 277 | E21: 39 | F21: =SUM(C21:E21) -> 1400 | G21: 185 | H21: 231 | I21: 190 | J21: 178 | K21: 201 | L21: 195 | M21: 220 | N21: =G21+H21+I21+J21+K21+L21+M21 -> 1400 | O21: 837 | P21: 563 | Q21: =SUM(O21:P21) -> 1400 | R21: 652 | S21: 748 | T21: =SUM(R21:S21) -> 1400 | U21: 1268 | V21: 302 | W21: 15 | X21: 472 | Y21: 154 | Z21: 29 | AA21: 24 | AB21: =SUM(U21:AA21) -> 2264 | AC21: 241 | AD21: 844 | AE21: 707 | AF21: 359 | AG21: 113 | AH21: =SUM(AC21:AG21) -> 2264 | AI21: 1587 | AJ21: 677 | AK21: =SUM(AI21:AJ21) -> 2264 | AL21: 1441 | AM21: 823 | AN21: =SUM(AL21:AM21) -> 2264 | AO21: 2221 | AP21: 43 | AQ21: =SUM(AO21:AP21) -> 2264 | AR21: 1693 | AS21: 482 | AT21: 0 | AU21: 0 | AV21: 89 | AW21: =SUM(AR21:AV21) -> 2264 | AX21: =AV21 -> 89 | AY21: 1753 | AZ21: 422 | BA21: =SUM(AX21:AZ21) -> 2264 | BB21: 1017 | BC21: 139 | BD21: 34 | BE21: 30 | BF21: 1 | BG21: 106 | BH21: 63 | BI21: 10 | BJ21: =SUM(BB21:BI21) -> 1400 | BK21: 10 | BL21: 40 | BM21: 75 | BN21: 0 | BO21: 261 | BP21: 0 | BQ21: 1014 | BR21: =SUM(BK21:BQ21) -> 1400 | BS21: 424 | BT21: 45 | BU21: 2202 | BV21: =SUM(BS21:BU21) -> 2671
B22: شعبان | C22: 1217 | D22: 255 | E22: 43 | F22: =SUM(C22:E22) -> 1515 | G22: 200 | H22: 249 | I22: 184 | J22: 190 | K22: 235 | L22: 240 | M22: 217 | N22: =G22+H22+I22+J22+K22+L22+M22 -> 1515 | O22: 959 | P22: 556 | Q22: =SUM(O22:P22) -> 1515 | R22: 752 | S22: 763 | T22: =SUM(R22:S22) -> 1515 | U22: 1567 | V22: 235 | W22: 9 | X22: 356 | Y22: 237 | Z22: 24 | AA22: 79 | AB22: =SUM(U22:AA22) -> 2507 | AC22: 259 | AD22: 744 | AE22: 727 | AF22: 568 | AG22: 209 | AH22: =SUM(AC22:AG22) -> 2507 | AI22: 1837 | AJ22: 670 | AK22: =SUM(AI22:AJ22) -> 2507 | AL22: 1664 | AM22: 843 | AN22: =SUM(AL22:AM22) -> 2507 | AO22: 2465 | AP22: 42 | AQ22: =SUM(AO22:AP22) -> 2507 | AR22: 1837 | AS22: 530 | AT22: 3 | AU22: 1 | AV22: 136 | AW22: =SUM(AR22:AV22) -> 2507 | AX22: =AV22 -> 136 | AY22: 1961 | AZ22: 410 | BA22: =SUM(AX22:AZ22) -> 2507 | BB22: 957 | BC22: 253 | BD22: 49 | BE22: 51 | BF22: 1 | BG22: 131 | BH22: 73 | BI22: 0 | BJ22: =SUM(BB22:BI22) -> 1515 | BK22: 0 | BL22: 4 | BM22: 16 | BN22: 0 | BO22: 116 | BP22: 0 | BQ22: 1379 | BR22: =SUM(BK22:BQ22) -> 1515 | BS22: 351 | BT22: 50 | BU22: 2372 | BV22: =SUM(BS22:BU22) -> 2773
B23: رمضان | C23: 1352 | D23: 187 | E23: 23 | F23: =SUM(C23:E23) -> 1562 | G23: 225 | H23: 219 | I23: 216 | J23: 190 | K23: 251 | L23: 237 | M23: 224 | N23: =G23+H23+I23+J23+K23+L23+M23 -> 1562 | O23: 950 | P23: 612 | Q23: =SUM(O23:P23) -> 1562 | R23: 861 | S23: 701 | T23: =SUM(R23:S23) -> 1562 | U23: 1456 | V23: 214 | W23: 5 | X23: 256 | Y23: 221 | Z23: 13 | AA23: 45 | AB23: =SUM(U23:AA23) -> 2210 | AC23: 244 | AD23: 645 | AE23: 561 | AF23: 468 | AG23: 292 | AH23: =SUM(AC23:AG23) -> 2210 | AI23: 1492 | AJ23: 718 | AK23: =SUM(AI23:AJ23) -> 2210 | AL23: 914 | AM23: 1296 | AN23: =SUM(AL23:AM23) -> 2210 | AO23: 2200 | AP23: 10 | AQ23: =SUM(AO23:AP23) -> 2210 | AR23: 1614 | AS23: 454 | AT23: 0 | AU23: 0 | AV23: 142 | AW23: =SUM(AR23:AV23) -> 2210 | AX23: =AV23 -> 142 | AY23: 1668 | AZ23: 400 | BA23: =SUM(AX23:AZ23) -> 2210 | BB23: 987 | BC23: 224 | BD23: 28 | BE23: 12 | BF23: 0 | BG23: 229 | BH23: 82 | BI23: 0 | BJ23: =SUM(BB23:BI23) -> 1562 | BK23: 0 | BL23: 0 | BM23: 0 | BN23: 0 | BO23: 263 | BP23: 0 | BQ23: 1299 | BR23: =SUM(BK23:BQ23) -> 1562 | BS23: 333 | BT23: 33 | BU23: 1875 | BV23: =SUM(BS23:BU23) -> 2241
B24: شوال | C24: 1205 | D24: 242 | E24: 51 | F24: =SUM(C24:E24) -> 1498 | G24: 206 | H24: 234 | I24: 172 | J24: 198 | K24: 253 | L24: 233 | M24: 202 | N24: =G24+H24+I24+J24+K24+L24+M24 -> 1498 | O24: 768 | P24: 730 | Q24: =SUM(O24:P24) -> 1498 | R24: 942 | S24: 556 | T24: =SUM(R24:S24) -> 1498 | U24: 1389 | V24: 221 | W24: 9 | X24: 265 | Y24: 205 | Z24: 52 | AA24: 78 | AB24: =SUM(U24:AA24) -> 2219 | AC24: 143 | AD24: 684 | AE24: 724 | AF24: 474 | AG24: 194 | AH24: =SUM(AC24:AG24) -> 2219 | AI24: 1638 | AJ24: 581 | AK24: =SUM(AI24:AJ24) -> 2219 | AL24: 1584 | AM24: 635 | AN24: =SUM(AL24:AM24) -> 2219 | AO24: 2149 | AP24: 70 | AQ24: =SUM(AO24:AP24) -> 2219 | AR24: 1916 | AS24: 186 | AT24: 0 | AU24: 0 | AV24: 117 | AW24: =SUM(AR24:AV24) -> 2219 | AX24: =AV24 -> 117 | AY24: 2069 | AZ24: 33 | BA24: =SUM(AX24:AZ24) -> 2219 | BB24: 1066 | BC24: 136 | BD24: 41 | BE24: 24 | BF24: 6 | BG24: 101 | BH24: 114 | BI24: 10 | BJ24: =SUM(BB24:BI24) -> 1498 | BK24: 46 | BL24: 43 | BM24: 76 | BN24: 49 | BO24: 113 | BP24: 0 | BQ24: 1171 | BR24: =SUM(BK24:BQ24) -> 1498 | BS24: 333 | BT24: 62 | BU24: 2166 | BV24: =SUM(BS24:BU24) -> 2561
B25: ذى القعدة | C25: 1122 | D25: 186 | E25: 26 | F25: =SUM(C25:E25) -> 1334 | G25: 234 | H25: 176 | I25: 180 | J25: 209 | K25: 184 | L25: 167 | M25: 184 | N25: =G25+H25+I25+J25+K25+L25+M25 -> 1334 | O25: 660 | P25: 674 | Q25: =SUM(O25:P25) -> 1334 | R25: 935 | S25: 399 | T25: =SUM(R25:S25) -> 1334 | U25: 1491 | V25: 189 | W25: 6 | X25: 241 | Y25: 114 | Z25: 49 | AA25: 20 | AB25: =SUM(U25:AA25) -> 2110 | AC25: 168 | AD25: 596 | AE25: 867 | AF25: 348 | AG25: 131 | AH25: =SUM(AC25:AG25) -> 2110 | AI25: 1413 | AJ25: 697 | AK25: =SUM(AI25:AJ25) -> 2110 | AL25: 1206 | AM25: 904 | AN25: =SUM(AL25:AM25) -> 2110 | AO25: 2095 | AP25: 15 | AQ25: =SUM(AO25:AP25) -> 2110 | AR25: 1737 | AS25: 296 | AT25: 0 | AU25: 2 | AV25: 75 | AW25: =SUM(AR25:AV25) -> 2110 | AX25: =AV25 -> 75 | AY25: 1789 | AZ25: 246 | BA25: =SUM(AX25:AZ25) -> 2110 | BB25: 946 | BC25: 144 | BD25: 39 | BE25: 13 | BF25: 2 | BG25: 100 | BH25: 84 | BI25: 6 | BJ25: =SUM(BB25:BI25) -> 1334 | BK25: 8 | BL25: 6 | BM25: 27 | BN25: 2 | BO25: 126 | BP25: 0 | BQ25: 1165 | BR25: =SUM(BK25:BQ25) -> 1334 | BS25: 264 | BT25: 33 | BU25: 1763 | BV25: =SUM(BS25:BU25) -> 2060
B26: ذى الحجة | C26: 1033 | D26: 214 | E26: 40 | F26: =SUM(C26:E26) -> 1287 | G26: 154 | H26: 177 | I26: 178 | J26: 214 | K26: 206 | L26: 167 | M26: 191 | N26: =G26+H26+I26+J26+K26+L26+M26 -> 1287 | O26: 688 | P26: 599 | Q26: =SUM(O26:P26) -> 1287 | R26: 763 | S26: 524 | T26: =SUM(R26:S26) -> 1287 | U26: 1211 | V26: 240 | W26: 16 | X26: 336 | Y26: 107 | Z26: 64 | AA26: 27 | AB26: =SUM(U26:AA26) -> 2001 | AC26: 214 | AD26: 638 | AE26: 790 | AF26: 257 | AG26: 102 | AH26: =SUM(AC26:AG26) -> 2001 | AI26: 1507 | AJ26: 494 | AK26: =SUM(AI26:AJ26) -> 2001 | AL26: 1404 | AM26: 597 | AN26: =SUM(AL26:AM26) -> 2001 | AO26: 1944 | AP26: 57 | AQ26: =SUM(AO26:AP26) -> 2001 | AR26: 1866 | AS26: 110 | AT26: 0 | AU26: 1 | AV26: 24 | AW26: =SUM(AR26:AV26) -> 2001 | AX26: =AV26 -> 24 | AY26: 1912 | AZ26: 65 | BA26: =SUM(AX26:AZ26) -> 2001 | BB26: 827 | BC26: 182 | BD26: 43 | BE26: 26 | BF26: 6 | BG26: 124 | BH26: 39 | BI26: 40 | BJ26: =SUM(BB26:BI26) -> 1287 | BK26: 18 | BL26: 36 | BM26: 31 | BN26: 15 | BO26: 106 | BP26: 0 | BQ26: 1081 | BR26: =SUM(BK26:BQ26) -> 1287 | BS26: 393 | BT26: 45 | BU26: 1827 | BV26: =SUM(BS26:BU26) -> 2265
B27: المجموع | C27: =SUM(C15:C26) -> 13298 | D27: =SUM(D15:D26) -> 2830 | E27: =SUM(E15:E26) -> 421 | F27: =SUM(F15:F26) -> 16549 | G27: =SUM(G15:G26) -> 2308 | H27: =SUM(H15:H26) -> 2415 | I27: =SUM(I15:I26) -> 2208 | J27: =SUM(J15:J26) -> 2285 | ... M27: =SUM(M15:M26) -> 2393 | N27: =G27+H27+I27+J27+K27+L27+M27 -> 16549 | O27: =SUM(O15:O26) -> 9450 | P27: =SUM(P15:P26) -> 7099 | Q27: =SUM(Q15:Q26) -> 16549 | R27: =SUM(R15:R26) -> 8757 | S27: =SUM(S15:S26) -> 7792 | T27: =SUM(T15:T26) -> 16549 | U27: =SUM(U15:U26) -> 15180 | V27: =SUM(V15:V26) -> 3090 | ... BV27: =SUM(BV15:BV26) -> 26927
A28: 1439 | B28: محرم | C28: 5047 | D28: 277 | E28: 75 | F28: =SUM(C28:E28) -> 5399 | G28: 919 | H28: 781 | I28: 625 | J28: 814 | K28: 702 | L28: 775 | M28: 783 | N28: =G28+H28+I28+J28+K28++L28+M28 -> 5399 | O28: 2819 | P28: 2580 | Q28: =SUM(O28:P28) -> 5399 | R28: 2452 | S28: 2947 | T28: =SUM(R28:S28) -> 5399 | U28: 1214 | V28: 1561 | W28: 63 | X28: 984 | Y28: 1475 | Z28: 102 | AA28: 0 | AB28: =SUM(U28:AA28) -> 5399 | AC28: 2417 | AD28: 4583 | AE28: 4390 | AF28: 1264 | AG28: 274 | AH28: =SUM(AC28:AG28) -> 12928 | AI28: 9522 | AJ28: 3406 | AK28: =SUM(AI28:AJ28) -> 12928 | AL28: 8115 | AM28: 4813 | AN28: =SUM(AL28:AM28) -> 12928 | AO28: 12901 | AP28: 27 | AQ28: =SUM(AO28:AP28) -> 12928 | AR28: 7892 | AS28: 2480 | AT28: 0 | AU28: 0 | AV28: 2556 | AW28: =+AR28+AS28+AT28+AU28+AV28 -> 12928 | AX28: =AV28 -> 2556 | AY28: 8611 | AZ28: 1761 | BA28: =SUM(AX28:AZ28) -> 12928 | BB28: 1647 | BC28: 1542 | BD28: 0 | BE28: 1 | BF28: 0 | BG28: 1132 | BH28: 261 | BI28: 816 | BJ28: =SUM(BB28:BI28) -> 5399 | BK28: 1022 | BL28: 974 | BM28: 891 | BN28: 1208 | BO28: 1304 | BP28: 0 | BQ28: 0 | BR28: =SUM(BK28:BQ28) -> 5399 | BS28: 393 | BT28: 100 | BU28: 12435 | BV28: =SUM(BS28:BU28) -> 12928
B29: صفر | C29: 5941 | D29: 255 | E29: 78 | F29: =SUM(C29:E29) -> 6274 | G29: 1427 | H29: 1407 | I29: 1434 | J29: 857 | K29: 421 | L29: 388 | M29: 340 | N29: =G29+H29+I29+J29+K29++L29+M29 -> 6274 | O29: 4589 | P29: 1685 | Q29: =SUM(O29:P29) -> 6274 | R29: 5367 | S29: 907 | T29: =SUM(R29:S29) -> 6274 | U29: 849 | V29: 663 | W29: 45 | X29: 79 | Y29: 1062 | Z29: 55 | AA29: 0 | AB29: =SUM(U29:AA29) -> 2753 | AC29: 1843 | AD29: 2281 | AE29: 2452 | AF29: 2053 | AG29: 1012 | AH29: =SUM(AC29:AG29) -> 9641 | AI29: 5968 | AJ29: 3673 | AK29: =SUM(AI29:AJ29) -> 9641 | AL29: 4883 | AM29: 4758 | AN29: =SUM(AL29:AM29) -> 9641 | AO29: 9594 | AP29: 47 | AQ29: =SUM(AO29:AP29) -> 9641 | AR29: 5072 | AS29: 2375 | AT29: 0 | AU29: 0 | AV29: 2194 | AW29: =SUM(AR29:AV29) -> 9641 | AX29: =AV29 -> 2194 | AY29: 5796 | AZ29: 1651 | BA29: =SUM(AX29:AZ29) -> 9641 | BB29: 2287 | BC29: 2274 | BD29: 0 | BE29: 3 | BF29: 0 | BG29: 1331 | BH29: 117 | BI29: 262 | BJ29: =SUM(BB29:BI29) -> 6274 | BK29: 1700 | BL29: 1940 | BM29: 898 | BN29: 739 | BO29: 997 | BP29: 0 | BQ29: 0 | BR29: =SUM(BK29:BQ29) -> 6274 | BS29: 433 | BT29: 98 | BU29: 9110 | BV29: =SUM(BS29:BU29) -> 9641
B30: ربيع أول | C30: 7808 | D30: 271 | E30: 87 | F30: =SUM(C30:E30) -> 8166 | G30: 1209 | H30: 1435 | I30: 1121 | J30: 1122 | K30: 1140 | L30: 1063 | M30: 1076 | N30: =G30+H30+I30+J30+K30++L30+M30 -> 8166 | O30: 4896 | P30: 3270 | Q30: =SUM(O30:P30) -> 8166 | R30: 3987 | S30: 4179 | T30: =SUM(R30:S30) -> 8166 | U30: 2377 | V30: 1648 | W30: 422 | X30: 1763 | Y30: 1055 | Z30: 901 | AA30: 0 | AB30: =SUM(U30:AA30) -> 8166 | AC30: 2722 | AD30: 3833 | AE30: 3697 | AF30: 3841 | AG30: 1852 | AH30: =SUM(AC30:AG30) -> 15945 | AI30: 9576 | AJ30: 6369 | AK30: =SUM(AI30:AJ30) -> 15945 | AL30: 10286 | AM30: 5659 | AN30: =SUM(AL30:AM30) -> 15945 | AO30: 15844 | AP30: 101 | AQ30: =SUM(AO30:AP30) -> 15945 | AR30: 6947 | AS30: 4399 | AT30: 0 | AU30: 0 | AV30: 4599 | AW30: =SUM(AR30:AV30) -> 15945 | AX30: =AV30 -> 4599 | AY30: 9285 | AZ30: 2061 | BA30: =SUM(AX30:AZ30) -> 15945 | BB30: 3195 | BC30: 2286 | BD30: 0 | BE30: 2 | BF30: 0 | BG30: 566 | BH30: 546 | BI30: 1571 | BJ30: =SUM(BB30:BI30) -> 8166 | BK30: 1669 | BL30: 1418 | BM30: 1255 | BN30: 1380 | BO30: 2444 | BP30: 0 | BQ30: 0 | BR30: =SUM(BK30:BQ30) -> 8166 | BS30: 455 | BT30: 105 | BU30: 15385 | BV30: =SUM(BS30:BU30) -> 15945
B31: ربيع ثانى | C31: 7821 | D31: 266 | E31: 79 | F31: =SUM(C31:E31) -> 8166 | G31: 1368 | H31: 1436 | I31: 1094 | J31: 1054 | K31: 1085 | L31: 1076 | M31: 1053 | N31: =G31+H31+I31+J31+K31++L31+M31 -> 8166 | O31: 4274 | P31: 3892 | Q31: =SUM(O31:P31) -> 8166 | R31: 4501 | S31: 3665 | T31: =SUM(R31:S31) -> 8166 | U31: 2114 | V31: 1648 | W31: 758 | X31: 1789 | Y31: 1147 | Z31: 710 | AA31: 0 | AB31: =SUM(U31:AA31) -> 8166 | AC31: 2855 | AD31: 3796 | AE31: 3541 | AF31: 3280 | AG31: 1709 | AH31: =SUM(AC31:AG31) -> 15181 | AI31: 8645 | AJ31: 6536 | AK31: =SUM(AI31:AJ31) -> 15181 | AL31: 10223 | AM31: 4958 | AN31: =SUM(AL31:AM31) -> 15181 | AO31: 14894 | AP31: 287 | AQ31: =SUM(AO31:AP31) -> 15181 | AR31: 6685 | AS31: 4277 | AT31: 0 | AU31: 0 | AV31: 4219 | AW31: =SUM(AR31:AV31) -> 15181 | AX31: =AV31 -> 4219 | AY31: 8141 | AZ31: 2821 | BA31: =SUM(AX31:AZ31) -> 15181 | BB31: 3398 | BC31: 2118 | BD31: 0 | BE31: 0 | BF31: 2 | BG31: 524 | BH31: 547 | BI31: 1577 | BJ31: =SUM(BB31:BI31) -> 8166 | BK31: 1688 | BL31: 1608 | BM31: 1512 | BN31: 1366 | BO31: 1992 | BP31: 0 | BQ31: 0 | BR31: =SUM(BK31:BQ31) -> 8166 | BS31: 427 | BT31: 91 | BU31: 15181 | BV31: =SUM(BS31:BU31) -> 15699
B32: جمادى أول | C32: 7923 | D32: 237 | E32: 81 | F32: =SUM(C32:E32) -> 8241 | G32: 1410 | H32: 1298 | I32: 1014 | J32: 1088 | K32: 1110 | L32: 1125 | M32: 1196 | N32: =G32+H32+I32+J32+K32++L32+M32 -> 8241 | O32: 4321 | P32: 3920 | Q32: =SUM(O32:P32) -> 8241 | R32: 4320 | S32: 3921 | T32: =SUM(R32:S32) -> 8241 | U32: 2118 | V32: 1759 | W32: 512 | X32: 1923 | Y32: 1126 | Z32: 803 | AA32: 0 | AB32: =SUM(U32:AA32) -> 8241 | AC32: 2844 | AD32: 3862 | AE32: 3623 | AF32: 3841 | AG32: 1721 | AH32: =SUM(AC32:AG32) -> 15891 | AI32: 9428 | AJ32: 6463 | AK32: =SUM(AI32:AJ32) -> 15891 | AL32: 10322 | AM32: 5569 | AN32: =SUM(AL32:AM32) -> 15891 | AO32: 15819 | AP32: 72 | AQ32: =SUM(AO32:AP32) -> 15891 | AR32: 6544 | AS32: 4377 | AT32: 0 | AU32: 0 | AV32: 4970 | AW32: =SUM(AR32:AV32) -> 15891 | AX32: =AV32 -> 4970 | AY32: 8176 | AZ32: 2745 | BA32: =SUM(AX32:AZ32) -> 15891 | BB32: 3973 | BC32: 2387 | BD32: 0 | BE32: 1 | BF32: 1 | BG32: 526 | BH32: 639 | BI32: 714 | BJ32: =SUM(BB32:BI32) -> 8241 | BK32: 1758 | BL32: 1511 | BM32: 1318 | BN32: 1426 | BO32: 2228 | BP32: 0 | BQ32: 0 | BR32: =SUM(BK32:BQ32) -> 8241 | BS32: 358 | BT32: 96 | BU32: 15437 | BV32: =SUM(BS32:BU32) -> 15891
B33: جمادى ثانى | C33: 6449 | D33: 259 | E33: 79 | F33: =SUM(C33:E33) -> 6787 | G33: 1015 | H33: 1003 | I33: 941 | J33: 956 | K33: 996 | L33: 991 | M33: 885 | N33: =G33+H33+I33+J33+K33++L33+M33 -> 6787 | O33: 3211 | P33: 3576 | Q33: =SUM(O33:P33) -> 6787 | R33: 3961 | S33: 2826 | T33: =SUM(R33:S33) -> 6787 | U33: 2579 | V33: 1246 | W33: 339 | X33: 721 | Y33: 1044 | Z33: 858 | AA33: 0 | AB33: =SUM(U33:AA33) -> 6787 | AC33: 2386 | AD33: 3864 | AE33: 3129 | AF33: 3285 | AG33: 1215 | AH33: =SUM(AC33:AG33) -> 13879 | AI33: 7821 | AJ33: 6058 | AK33: =SUM(AI33:AJ33) -> 13879 | AL33: 6873 | AM33: 7006 | AN33: =SUM(AL33:AM33) -> 13879 | AO33: 13801 | AP33: 78 | AQ33: =SUM(AO33:AP33) -> 13879 | AR33: 5399 | AS33: 4582 | AT33: 0 | AU33: 0 | AV33: 3898 | AW33: =SUM(AR33:AV33) -> 13879 | AX33: =AV33 -> 3898 | AY33: 7489 | AZ33: 2492 | BA33: =SUM(AX33:AZ33) -> 13879 | BB33: 3736 | BC33: 1309 | BD33: 0 | BE33: 1 | BF33: 13 | BG33: 643 | BH33: 794 | BI33: 291 | BJ33: =SUM(BB33:BI33) -> 6787 | BK33: 1209 | BL33: 581 | BM33: 1187 | BN33: 1719 | BO33: 2091 | BP33: 0 | BQ33: 0 | BR33: =SUM(BK33:BQ33) -> 6787 | BS33: 379 | BT33: 96 | BU33: 13404 | BV33: =SUM(BS33:BU33) -> 13879
B34: رجب | C34: 6955 | D34: 227 | E34: 65 | F34: =SUM(C34:E34) -> 7247 | G34: 1164 | H34: 1222 | I34: 1015 | J34: 1051 | K34: 1023 | L34: 863 | M34: 909 | N34: =G34+H34+I34+J34+K34++L34+M34 -> 7247 | O34: 3839 | P34: 3408 | Q34: =SUM(O34:P34) -> 7247 | R34: 3788 | S34: 3459 | T34: =SUM(R34:S34) -> 7247 | U34: 2347 | V34: 1908 | W34: 64 | X34: 983 | Y34: 1419 | Z34: 526 | AA34: 0 | AB34: =SUM(U34:AA34) -> 7247 | AC34: 2916 | AD34: 3605 | AE34: 3411 | AF34: 3629 | AG34: 1185 | AH34: =SUM(AC34:AG34) -> 14746 | AI34: 9281 | AJ34: 5465 | AK34: =SUM(AI34:AJ34) -> 14746 | AL34: 10201 | AM34: 4545 | AN34: =SUM(AL34:AM34) -> 14746 | AO34: 14695 | AP34: 51 | AQ34: =SUM(AO34:AP34) -> 14746 | AR34: 6614 | AS34: 4231 | AT34: 0 | AU34: 0 | AV34: 3901 | AW34: =SUM(AR34:AV34) -> 14746 | AX34: =AV34 -> 3901 | AY34: 8257 | AZ34: 2588 | BA34: =SUM(AX34:AZ34) -> 14746 | BB34: 4522 | BC34: 1596 | BD34: 0 | BE34: 2 | BF34: 0 | BG34: 581 | BH34: 491 | BI34: 55 | BJ34: =SUM(BB34:BI34) -> 7247 | BK34: 1809 | BL34: 1214 | BM34: 1147 | BN34: 1165 | BO34: 1912 | BP34: 0 | BQ34: 0 | BR34: =SUM(BK34:BQ34) -> 7247 | BS34: 383 | BT34: 83 | BU34: 14280 | BV34: =SUM(BS34:BU34) -> 14746
B35: شعبان | C35: 6516 | D35: 258 | E35: 63 | F35: =SUM(C35:E35) -> 6837 | G35: 1162 | H35: 970 | I35: 1093 | J35: 899 | K35: 853 | L35: 947 | M35: 913 | N35: =G35+H35+I35+J35+K35++L35+M35 -> 6837 | O35: 4017 | P35: 2820 | Q35: =SUM(O35:P35) -> 6837 | R35: 4240 | S35: 2597 | T35: =SUM(R35:S35) -> 6837 | U35: 3869 | V35: 1149 | W35: 44 | X35: 703 | Y35: 984 | Z35: 88 | AA35: 0 | AB35: =SUM(U35:AA35) -> 6837 | AC35: 2791 | AD35: 4633 | AE35: 4920 | AF35: 1933 | AG35: 641 | AH35: =SUM(AC35:AG35) -> 14918 | AI35: 9513 | AJ35: 5405 | AK35: =SUM(AI35:AJ35) -> 14918 | AL35: 8447 | AM35: 6471 | AN35: =SUM(AL35:AM35) -> 14918 | AO35: 14885 | AP35: 33 | AQ35: =SUM(AO35:AP35) -> 14918 | AR35: 8519 | AS35: 3853 | AT35: 0 | AU35: 0 | AV35: 2546 | AW35: =SUM(AR35:AV35) -> 14918 | AX35: =AV35 -> 2546 | AY35: 10365 | AZ35: 2007 | BA35: =SUM(AX35:AZ35) -> 14918 | BB35: 4892 | BC35: 1423 | BD35: 31 | BE35: 7 | BF35: 0 | BG35: 257 | BH35: 227 | BI35: 0 | BJ35: =SUM(BB35:BI35) -> 6837 | BK35: 637 | BL35: 901 | BM35: 1813 | BN35: 896 | BO35: 2590 | BP35: 0 | BQ35: 0 | BR35: =SUM(BK35:BQ35) -> 6837 | BS35: 393 | BT35: 75 | BU35: 14450 | BV35: =SUM(BS35:BU35) -> 14918
B36: رمضان | C36: 4997 | D36: 229 | E36: 71 | F36: =SUM(C36:E36) -> 5297 | G36: 851 | H36: 777 | I36: 731 | J36: 741 | K36: 765 | L36: 722 | M36: 710 | N36: =SUM(G36:M36) -> 5297 | O36: 2170 | P36: 3127 | Q36: =SUM(O36:P36) -> 5297 | R36: 3862 | S36: 1435 | T36: =SUM(R36:S36) -> 5297 | U36: 2372 | V36: 1350 | W36: 45 | X36: 989 | Y36: 505 | Z36: 36 | AA36: 0 | AB36: =SUM(U36:AA36) -> 5297 | AC36: 2405 | AD36: 3791 | AE36: 3112 | AF36: 2150 | AG36: 1301 | AH36: =SUM(AC36:AG36) -> 12759 | AI36: 8499 | AJ36: 4260 | AK36: =SUM(AI36:AJ36) -> 12759 | AL36: 9168 | AM36: 3591 | AN36: =SUM(AL36:AM36) -> 12759 | AO36: 12727 | AP36: 32 | AQ36: =SUM(AO36:AP36) -> 12759 | AR36: 6402 | AS36: 3830 | AT36: 0 | AU36: 0 | AV36: 2527 | AW36: =SUM(AR36:AV36) -> 12759 | AX36: =AV36 -> 2527 | AY36: 8122 | AZ36: 2110 | BA36: =SUM(AX36:AZ36) -> 12759 | BB36: 3301 | BC36: 811 | BD36: 25 | BE36: 0 | BF36: 0 | BG36: 467 | BH36: 693 | BI36: 0 | BJ36: =SUM(BB36:BI36) -> 5297 | BK36: 638 | BL36: 645 | BM36: 1078 | BN36: 988 | BO36: 1948 | BP36: 0 | BQ36: 0 | BR36: =SUM(BK36:BQ36) -> 5297 | BS36: 335 | BT36: 82 | BU36: 12342 | BV36: =SUM(BS36:BU36) -> 12759
B37: شوال | C37: 5226 | D37: 238 | E37: 80 | F37: =SUM(C37:E37) -> 5544 | G37: 755 | H37: 633 | I37: 783 | J37: 833 | K37: 840 | L37: 835 | M37: 865 | N37: =G37+H37+I37+J37+K37++L37+M37 -> 5544 | O37: 2614 | P37: 2930 | Q37: =SUM(O37:P37) -> 5544 | R37: 2798 | S37: 2746 | T37: =SUM(R37:S37) -> 5544 | U37: 2238 | V37: 1439 | W37: 479 | X37: 751 | Y37: 596 | Z37: 41 | AA37: 0 | AB37: =SUM(U37:AA37) -> 5544 | AC37: 1914 | AD37: 2259 | AE37: 2371 | AF37: 1991 | AG37: 1882 | AH37: =SUM(AC37:AG37) -> 10417 | AI37: 4690 | AJ37: 5727 | AK37: =SUM(AI37:AJ37) -> 10417 | AL37: 5423 | AM37: 4994 | AN37: =SUM(AL37:AM37) -> 10417 | AO37: 9899 | AP37: 518 | AQ37: =SUM(AO37:AP37) -> 10417 | AR37: 4346 | AS37: 3371 | AT37: 0 | AU37: 0 | AV37: 2700 | AW37: =SUM(AR37:AV37) -> 10417 | AX37: =AV37 -> 2700 | AY37: 4075 | AZ37: 3642 | BA37: =SUM(AX37:AZ37) -> 10417 | BB37: 1377 | BC37: 2402 | BD37: 489 | BE37: 4 | BF37: 0 | BG37: 764 | BH37: 508 | BI37: 0 | BJ37: =SUM(BB37:BI37) -> 5544 | BK37: 957 | BL37: 1018 | BM37: 1190 | BN37: 1143 | BO37: 1236 | BP37: 0 | BQ37: 0 | BR37: =SUM(BK37:BQ37) -> 5544 | BS37: 384 | BT37: 100 | BU37: 9933 | BV37: =SUM(BS37:BU37) -> 10417
B38: ذى القعدة | C38: 5620 | D38: 197 | E38: 54 | F38: =SUM(C38:E38) -> 5871 | G38: 923 | H38: 852 | I38: 912 | J38: 849 | K38: 847 | L38: 820 | M38: 668 | N38: =G38+H38+I38+J38+K38++L38+M38 -> 5871 | O38: 2475 | P38: 3396 | Q38: =SUM(O38:P38) -> 5871 | R38: 2911 | S38: 2960 | T38: =SUM(R38:S38) -> 5871 | U38: 2833 | V38: 1549 | W38: 47 | X38: 899 | Y38: 507 | Z38: 36 | AA38: 0 | AB38: =SUM(U38:AA38) -> 5871 | AC38: 2311 | AD38: 3536 | AE38: 3240 | AF38: 2176 | AG38: 1382 | AH38: =SUM(AC38:AG38) -> 12645 | AI38: 8735 | AJ38: 3910 | AK38: =SUM(AI38:AJ38) -> 12645 | AL38: 9211 | AM38: 3434 | AN38: =SUM(AL38:AM38) -> 12645 | AO38: 12599 | AP38: 46 | AQ38: =SUM(AO38:AP38) -> 12645 | AR38: 6422 | AS38: 3795 | AT38: 0 | AU38: 0 | AV38: 2428 | AW38: =SUM(AR38:AV38) -> 12645 | AX38: =AV38 -> 2428 | AY38: 8105 | AZ38: 2112 | BA38: =SUM(AX38:AZ38) -> 12645 | BB38: 3734 | BC38: 974 | BD38: 27 | BE38: 0 | BF38: 0 | BG38: 454 | BH38: 382 | BI38: 300 | BJ38: =SUM(BB38:BI38) -> 5871 | BK38: 677 | BL38: 782 | BM38: 1011 | BN38: 967 | BO38: 2134 | BP38: 0 | BQ38: 300 | BR38: =SUM(BK38:BQ38) -> 5871 | BS38: 313 | BT38: 65 | BU38: 12267 | BV38: =SUM(BS38:BU38) -> 12645
B39: ذى الحجة | C39: 5786 | D39: 183 | E39: 86 | F39: =SUM(C39:E39) -> 6055 | G39: 914 | H39: 921 | I39: 685 | J39: 641 | K39: 692 | L39: 721 | M39: 1481 | N39: =G39+H39+I39+J39+K39++L39+M39 -> 6055 | O39: 3411 | P39: 2644 | Q39: =SUM(O39:P39) -> 6055 | R39: 2908 | S39: 3147 | T39: =SUM(R39:S39) -> 6055 | U39: 3111 | V39: 1659 | W39: 26 | X39: 641 | Y39: 436 | Z39: 182 | AA39: 0 | AB39: =SUM(U39:AA39) -> 6055 | AC39: 2429 | AD39: 3601 | AE39: 3460 | AF39: 2199 | AG39: 2015 | AH39: =SUM(AC39:AG39) -> 13704 | AI39: 8865 | AJ39: 4839 | AK39: =SUM(AI39:AJ39) -> 13704 | AL39: 9221 | AM39: 4483 | AN39: =SUM(AL39:AM39) -> 13704 | AO39: 13675 | AP39: 29 | AQ39: =SUM(AO39:AP39) -> 13704 | AR39: 6792 | AS39: 4396 | AT39: 0 | AU39: 0 | AV39: 2516 | AW39: =SUM(AR39:AV39) -> 13704 | AX39: =AV39 -> 2516 | AY39: 9154 | AZ39: 2034 | BA39: =SUM(AX39:AZ39) -> 13704 | BB39: 3827 | BC39: 839 | BD39: 37 | BE39: 0 | BF39: 1 | BG39: 382 | BH39: 969 | BI39: 0 | BJ39: =SUM(BB39:BI39) -> 6055 | BK39: 704 | BL39: 692 | BM39: 1501 | BN39: 947 | BO39: 2211 | BP39: 0 | BQ39: 0 | BR39: =SUM(BK39:BQ39) -> 6055 | BS39: 301 | BT39: 100 | BU39: 13303 | BV39: =SUM(BS39:BU39) -> 13704
B40: المجموع | C40: =SUM(C28:C39) -> 76089 | D40: =SUM(D28:D39) -> 2897 | E40: =SUM(E28:E39) -> 898 | F40: =SUM(F28:F39) -> 79884 | G40: =SUM(G28:G39) -> 13117 | H40: =SUM(H28:H39) -> 12735 | I40: =SUM(I28:I39) -> 11448 | J40: =SUM(J28:J39) -> 10905 | ... M40: =SUM(M28:M39) -> 10879 | N40: =G40+H40+I40+J40+K40++L40+M40 -> 79884 | O40: =SUM(O28:O39) -> 42636 | P40: =SUM(P28:P39) -> 37248 | Q40: =SUM(Q28:Q39) -> 79884 | R40: =SUM(R28:R39) -> 45095 | S40: =SUM(S28:S39) -> 34789 | T40: =SUM(T28:T39) -> 79884 | U40: =SUM(U28:U39) -> 28021 | V40: =SUM(V28:V39) -> 17579 | ... BV40: =SUM(BV28:BV39) -> 163172
...

Sheet القريات
A1: الشهر | B1: حادث تلفيات | C1: حادث اصابات | D1: حادث وفيات | E1: مجموع عدد الحوادث | F1: السبت | G1: الا حد | H1: الاثنين | I1: الثلاثاء | J1: الا ربعاء | K1: الخميس | L1: الجمعة | M1: مجموع عدد الحوادث لجميع الأيام | N1: نهارا | O1: ليلا | P1: مجموع عدد الحوادث حسب الوقت | Q1: داخل المدينة | R1: خارج المدينة | S1: مجموع عدد الحوادث حسب مكان الحادث | T1: صغيرة | U1: جيب | V1: حافلة | W1: ونيت | X1: نقل | Y1: وايت | Z1: اخرى | AA1: مجموع عدد السيارات المشتركة في الحوادث حسب الطراز | AB1: -18 | AC1: 18+ | AD1: 30+ | AE1: 40+ | AF1: 50+ | AG1: المجموع حسب العمر | AH1: سعودي | AI1: اجنبي | AJ1: المجموع حسب الجنسية | AK1: متزوج | AL1: اعزب | AM1: المجموع حسب الحالة الاجتماعية | AN1: متعلم | AO1: امى | AP1: المجموع حسب الحالة التعليمية | AQ1: نوع الرخصة خصوصى | AR1: نوع الرخصة عمومى | AS1: نوع الرخصة اليات | AT1: نوع الرخصة دراجة | AU1: السائق لا يحمل رخصة قيادة | AV1: المجموع | AW1: السائق لا يحمل رخصة قيادة | AX1: الرخصة سارية | AY1: الرخصة منتهية | AZ1: المجموع | BA1: تصادم مع سيارة | BB1: تصادم مع جسم ثابت | BC1: دهس مشاة | BD1: دهس حيوان | BE1: حريق | BF1: انقلاب | BG1: خروج عن الطريق | BH1: أخرى | BI1: المجموع | BJ1: توقف غير نظامى | BK1: دوران غير نظامى | BL1: تجاوز غير نظامى | BM1: عدم التقيد بالاشارة | BN1: السرعة الزائدة | BO1: السائق تحت تأثير مخدر | BP1: اخرى | BQ1: مجموع الحوادث حسب سبب الحادث | BR1: عدد المصابين | BS1: عدد المتوفين (القتلى) | BT1: سليم | BU1: مجموع الأشخاص المشمولين بالحوادث
A2: محرم | B2: 311 | C2: 24 | D2: 5 | E2: =SUM(B2:D2) -> 340 | F2: 42 | G2: 36 | H2: 45 | I2: 45 | J2: 58 | K2: 65 | L2: 49 | M2: =F2+G2+H2+I2+J2+K2+L2 -> 340 | N2: 66 | O2: 274 | P2: =SUM(N2:O2) -> 340 | Q2: 323 | R2: 17 | S2: =SUM(Q2:R2) -> 340 | T2: 277 | U2: 196 | V2: 0 | W2: 0 | X2: 185 | Y2: 2 | Z2: 2 | AA2: =SUM(T2:Z2) -> 662 | AB2: 68 | AC2: 456 | AD2: 98 | AE2: 32 | AF2: 8 | AG2: =SUM(AB2:AF2) -> 662 | AH2: 525 | AI2: 137 | AJ2: =SUM(AH2:AI2) -> 662 | AK2: 507 | AL2: 155 | AM2: =SUM(AK2:AL2) -> 662 | AN2: 661 | AO2: 1 | AP2: =SUM(AN2:AO2) -> 662 | AQ2: 626 | AR2: 19 | AS2: 0 | AT2: 0 | AU2: 17 | AV2: =+AQ2+AR2+AS2+AT2+AU2 -> 662 | AW2: =AU2 -> 17 | AX2: 607 | AY2: 38 | AZ2: =SUM(AW2:AY2) -> 662 | BA2: 322 | BB2: 7 | BC2: 2 | BD2: 0 | BE2: 0 | BF2: 8 | BG2: 0 | BH2: 1 | BI2: =SUM(BA2:BH2) -> 340 | BJ2: 0 | BK2: 34 | BL2: 65 | BM2: 0 | BN2: 95 | BO2: 0 | BP2: 146 | BQ2: =SUM(BJ2:BP2) -> 340 | BR2: 29 | BS2: 5 | BT2: 643 | BU2: =SUM(BR2:BT2) -> 677
A3: صفر | B3: 293 | C3: 30 | D3: 7 | E3: =SUM(B3:D3) -> 330 | F3: 45 | G3: 51 | H3: 42 | I3: 46 | J3: 44 | K3: 53 | L3: 49 | M3: =F3+G3+H3+I3+J3+K3+L3 -> 330 | N3: 73 | O3: 257 | P3: =SUM(N3:O3) -> 330 | Q3: 310 | R3: 20 | S3: =SUM(Q3:R3) -> 330 | T3: 272 | U3: 181 | V3: 2 | W3: 5 | X3: 177 | Y3: 2 | Z3: 1 | AA3: =SUM(T3:Z3) -> 640 | AB3: 62 | AC3: 431 | AD3: 92 | AE3: 42 | AF3: 13 | AG3: =SUM(AB3:AF3) -> 640 | AH3: 503 | AI3: 137 | AJ3: =SUM(AH3:AI3) -> 640 | AK3: 463 | AL3: 177 | AM3: =SUM(AK3:AL3) -> 640 | AN3: 639 | AO3: 1 | AP3: =SUM(AN3:AO3) -> 640 | AQ3: 602 | AR3: 19 | AS3: 0 | AT3: 1 | AU3: 18 | AV3: =SUM(AQ3:AU3) -> 640 | AW3: =AU3 -> 18 | AX3: 589 | AY3: 33 | AZ3: =SUM(AW3:AY3) -> 640 | BA3: 306 | BB3: 1 | BC3: 10 | BD3: 0 | BE3: 0 | BF3: 12 | BG3: 1 | BH3: 0 | BI3: =SUM(BA3:BH3) -> 330 | BJ3: 3 | BK3: 29 | BL3: 58 | BM3: 0 | BN3: 90 | BO3: 0 | BP3: 150 | BQ3: =SUM(BJ3:BP3) -> 330 | BR3: 54 | BS3: 13 | BT3: 614 | BU3: =SUM(BR3:BT3) -> 681
A4: ربيع أول | B4: 347 | C4: 12 | D4: 4 | E4: =SUM(B4:D4) -> 363 | F4: 62 | G4: 52 | H4: 37 | I4: 48 | J4: 57 | K4: 52 | L4: 55 | M4: =SUM(F4:L4) -> 363 | N4: 95 | O4: 268 | P4: =SUM(N4:O4) -> 363 | Q4: 351 | R4: 12 | S4: =SUM(Q4:R4) -> 363 | T4: 348 | U4: 185 | V4: 2 | W4: 2 | X4: 179 | Y4: 0 | Z4: 0 | AA4: =SUM(T4:Z4) -> 716 | AB4: 57 | AC4: 457 | AD4: 133 | AE4: 60 | AF4: 9 | AG4: =SUM(AB4:AF4) -> 716 | AH4: 583 | AI4: 133 | AJ4: =SUM(AH4:AI4) -> 716 | AK4: 527 | AL4: 189 | AM4: =SUM(AK4:AL4) -> 716 | AN4: 708 | AO4: 8 | AP4: =SUM(AN4:AO4) -> 716 | AQ4: 680 | AR4: 20 | AS4: 0 | AT4: 0 | AU4: 16 | AV4: =SUM(AQ4:AU4) -> 716 | AW4: =AU4 -> 16 | AX4: 660 | AY4: 40 | AZ4: =SUM(AW4:AY4) -> 716 | BA4: 346 | BB4: 7 | BC4: 2 | BD4: 0 | BE4: 0 | BF4: 8 | BG4: 0 | BH4: 0 | BI4: =SUM(BA4:BH4) -> 363 | BJ4: 6 | BK4: 32 | BL4: 60 | BM4: 0 | BN4: 109 | BO4: 0 | BP4: 156 | BQ4: =SUM(BJ4:BP4) -> 363 | BR4: 25 | BS4: 4 | BT4: 704 | BU4: =SUM(BR4:BT4) -> 733
A5: ربيع ثانى | B5: 286 | C5: 16 | D5: 5 | E5: =SUM(B5:D5) -> 307 | F5: 40 | G5: 51 | H5: 41 | I5: 54 | J5: 41 | K5: 39 | L5: 41 | M5: =SUM(F5:L5) -> 307 | N5: 64 | O5: 243 | P5: =SUM(N5:O5) -> 307 | Q5: 297 | R5: 10 | S5: =SUM(Q5:R5) -> 307 | T5: 288 | U5: 166 | V5: 0 | W5: 0 | X5: 147 | Y5: 1 | Z5: 0 | AA5: =SUM(T5:Z5) -> 602 | AB5: 58 | AC5: 385 | AD5: 107 | AE5: 46 | AF5: 6 | AG5: =SUM(AB5:AF5) -> 602 | AH5: 497 | AI5: 105 | AJ5: =SUM(AH5:AI5) -> 602 | AK5: 474 | AL5: 128 | AM5: =SUM(AK5:AL5) -> 602 | AN5: 596 | AO5: 6 | AP5: =SUM(AN5:AO5) -> 602 | AQ5: 577 | AR5: 17 | AS5: 0 | AT5: 0 | AU5: 8 | AV5: =SUM(AQ5:AU5) -> 602 | AW5: =AU5 -> 8 | AX5: 562 | AY5: 32 | AZ5: =SUM(AW5:AY5) -> 602 | BA5: 298 | BB5: 4 | BC5: 3 | BD5: 1 | BE5: 0 | BF5: 1 | BG5: 0 | BH5: 0 | BI5: =SUM(BA5:BH5) -> 307 | BJ5: 0 | BK5: 28 | BL5: 65 | BM5: 0 | BN5: 85 | BO5: 0 | BP5: 129 | BQ5: =SUM(BJ5:BP5) -> 307 | BR5: 16 | BS5: 5 | BT5: 601 | BU5: =SUM(BR5:BT5) -> 622
A6: جمادى أول | B6: 254 | C6: 20 | D6: 7 | E6: =SUM(B6:D6) -> 281 | F6: 17 | G6: 26 | H6: 45 | I6: 61 | J6: 47 | K6: 44 | L6: 41 | M6: =SUM(F6:L6) -> 281 | N6: 85 | O6: 196 | P6: =SUM(N6:O6) -> 281 | Q6: 265 | R6: 16 | S6: =SUM(Q6:R6) -> 281 | T6: 284 | U6: 132 | V6: 1 | W6: 1 | X6: 127 | Y6: 0 | Z6: 4 | AA6: =SUM(T6:Z6) -> 549 | AB6: 80 | AC6: 326 | AD6: 93 | AE6: 41 | AF6: 7 | AG6: =SUM(AB6:AF6) -> 547 | AH6: 453 | AI6: 94 | AJ6: =SUM(AH6:AI6) -> 547 | AK6: 434 | AL6: 113 | AM6: =SUM(AK6:AL6) -> 547 | AN6: 539 | AO6: 8 | AP6: =SUM(AN6:AO6) -> 547 | AQ6: 509 | AR6: 17 | AS6: 2 | AT6: 0 | AU6: 19 | AV6: =SUM(AQ6:AU6) -> 547 | AW6: =AU6 -> 19 | AX6: 490 | AY6: 38 | AZ6: =SUM(AW6:AY6) -> 547 | BA6: 267 | BB6: 7 | BC6: 5 | BD6: 2 | BE6: 0 | BF6: 0 | BG6: 0 | BH6: 0 | BI6: =SUM(BA6:BH6) -> 281 | BJ6: 0 | BK6: 30 | BL6: 62 | BM6: 0 | BN6: 84 | BO6: 0 | BP6: 105 | BQ6: =SUM(BJ6:BP6) -> 281 | BR6: 21 | BS6: 7 | BT6: 543 | BU6: =SUM(BR6:BT6) -> 571
A7: جمادى ثانى | B7: 288 | C7: 13 | D7: 2 | E7: =SUM(B7:D7) -> 303 | F7: 47 | G7: 38 | H7: 39 | I7: 43 | J7: 41 | K7: 50 | L7: 45 | M7: =SUM(F7:L7) -> 303 | N7: 72 | O7: 231 | P7: =SUM(N7:O7) -> 303 | Q7: 295 | R7: 8 | S7: =SUM(Q7:R7) -> 303 | T7: 272 | U7: 173 | V7: 0 | W7: 0 | X7: 149 | Y7: 0 | Z7: 1 | AA7: =SUM(T7:Z7) -> 595 | AB7: 54 | AC7: 382 | AD7: 107 | AE7: 48 | AF7: 4 | AG7: =SUM(AB7:AF7) -> 595 | AH7: 492 | AI7: 103 | AJ7: =SUM(AH7:AI7) -> 595 | AK7: 456 | AL7: 139 | AM7: =SUM(AK7:AL7) -> 595 | AN7: 589 | AO7: 6 | AP7: =SUM(AN7:AO7) -> 595 | AQ7: 572 | AR7: 12 | AS7: 0 | AT7: 0 | AU7: 11 | AV7: =SUM(AQ7:AU7) -> 595 | AW7: =AU7 -> 11 | AX7: 550 | AY7: 34 | AZ7: =SUM(AW7:AY7) -> 595 | BA7: 287 | BB7: 7 | BC7: 2 | BD7: 1 | BE7: 0 | BF7: 6 | BG7: 0 | BH7: 0 | BI7: =SUM(BA7:BH7) -> 303 | BJ7: 0 | BK7: 30 | BL7: 65 | BM7: 0 | BN7: 83 | BO7: 0 | BP7: 125 | BQ7: =SUM(BJ7:BP7) -> 303 | BR7: 20 | BS7: 3 | BT7: 583 | BU7: =SUM(BR7:BT7) -> 606
A8: رجب | B8: 285 | C8: 27 | D8: 0 | E8: =SUM(B8:D8) -> 312 | F8: 53 | G8: 44 | H8: 47 | I8: 42 | J8: 41 | K8: 42 | L8: 43 | M8: =SUM(F8:L8) -> 312 | N8: 66 | O8: 246 | P8: =SUM(N8:O8) -> 312 | Q8: 301 | R8: 11 | S8: =SUM(Q8:R8) -> 312 | T8: 261 | U8: 183 | V8: 0 | W8: 0 | X8: 166 | Y8: 0 | Z8: 1 | AA8: =SUM(T8:Z8) -> 611 | AB8: 57 | AC8: 415 | AD8: 92 | AE8: 37 | AF8: 10 | AG8: =SUM(AB8:AF8) -> 611 | AH8: 487 | AI8: 124 | AJ8: =SUM(AH8:AI8) -> 611 | AK8: 453 | AL8: 158 | AM8: =SUM(AK8:AL8) -> 611 | AN8: 607 | AO8: 4 | AP8: =SUM(AN8:AO8) -> 611 | AQ8: 586 | AR8: 9 | AS8: 0 | AT8: 0 | AU8: 16 | AV8: =SUM(AQ8:AU8) -> 611 | AW8: =AU8 -> 16 | AX8: 568 | AY8: 27 | AZ8: =SUM(AW8:AY8) -> 611 | BA8: 295 | BB8: 4 | BC8: 6 | BD8: 3 | BE8: 0 | BF8: 1 | BG8: 0 | BH8: 3 | BI8: =SUM(BA8:BH8) -> 312 | BJ8: 0 | BK8: 30 | BL8: 62 | BM8: 0 | BN8: 76 | BO8: 0 | BP8: 144 | BQ8: =SUM(BJ8:BP8) -> 312 | BR8: 43 | BS8: 0 | BT8: 597 | BU8: =SUM(BR8:BT8) -> 640
A9: شعبان | B9: 283 | C9: 17 | D9: 5 | E9: =SUM(B9:D9) -> 305 | F9: 36 | G9: 60 | H9: 44 | I9: 43 | J9: 46 | K9: 34 | L9: 42 | M9: =SUM(F9:L9) -> 305 | N9: 77 | O9: 228 | P9: =SUM(N9:O9) -> 305 | Q9: 290 | R9: 15 | S9: =SUM(Q9:R9) -> 305 | T9: 271 | U9: 172 | V9: 0 | W9: 0 | X9: 155 | Y9: 0 | Z9: 1 | AA9: =SUM(T9:Z9) -> 599 | AB9: 53 | AC9: 378 | AD9: 112 | AE9: 49 | AF9: 7 | AG9: =SUM(AB9:AF9) -> 599 | AH9: 492 | AI9: 107 | AJ9: =SUM(AH9:AI9) -> 599 | AK9: 458 | AL9: 141 | AM9: =SUM(AK9:AL9) -> 599 | AN9: 591 | AO9: 8 | AP9: =SUM(AN9:AO9) -> 599 | AQ9: 576 | AR9: 14 | AS9: 0 | AT9: 0 | AU9: 9 | AV9: =SUM(AQ9:AU9) -> 599 | AW9: =AU9 -> 9 | AX9: 554 | AY9: 36 | AZ9: =SUM(AW9:AY9) -> 599 | BA9: 287 | BB9: 10 | BC9: 3 | BD9: 0 | BE9: 0 | BF9: 4 | BG9: 0 | BH9: 1 | BI9: =SUM(BA9:BH9) -> 305 | BJ9: 0 | BK9: 28 | BL9: 60 | BM9: 2 | BN9: 89 | BO9: 0 | BP9: 126 | BQ9: =SUM(BJ9:BP9) -> 305 | BR9: 40 | BS9: 8 | BT9: 586 | BU9: =SUM(BR9:BT9) -> 634
A10: رمضان | B10: 289 | C10: 15 | D10: 6 | E10: =SUM(B10:D10) -> 310 | F10: 45 | G10: 39 | H10: 45 | I10: 42 | J10: 38 | K10: 43 | L10: 58 | M10: =SUM(F10:L10) -> 310 | N10: 76 | O10: 234 | P10: =SUM(N10:O10) -> 310 | Q10: 298 | R10: 12 | S10: =SUM(Q10:R10) -> 310 | T10: 282 | U10: 170 | V10: 0 | W10: 0 | X10: 155 | Y10: 0 | Z10: 0 | AA10: =SUM(T10:Z10) -> 607 | AB10: 57 | AC10: 395 | AD10: 102 | AE10: 46 | AF10: 7 | AG10: =SUM(AB10:AF10) -> 607 | AH10: 496 | AI10: 111 | AJ10: =SUM(AH10:AI10) -> 607 | AK10: 455 | AL10: 152 | AM10: =SUM(AK10:AL10) -> 607 | AN10: 601 | AO10: 6 | AP10: =SUM(AN10:AO10) -> 607 | AQ10: 577 | AR10: 14 | AS10: 0 | AT10: 0 | AU10: 16 | AV10: =SUM(AQ10:AU10) -> 607 | AW10: =AU10 -> 16 | AX10: 556 | AY10: 35 | AZ10: =SUM(AW10:AY10) -> 607 | BA10: 295 | BB10: 4 | BC10: 6 | BD10: 0 | BE10: 0 | BF10: 5 | BG10: 0 | BH10: 0 | BI10: =SUM(BA10:BH10) -> 310 | BJ10: 0 | BK10: 31 | BL10: 64 | BM10: 0 | BN10: 84 | BO10: 0 | BP10: 131 | BQ10: =SUM(BJ10:BP10) -> 310 | BR10: 33 | BS10: 8 | BT10: 590 | BU10: =SUM(BR10:BT10) -> 631
A11: شوال | B11: 303 | C11: 14 | D11: 1 | E11: =SUM(B11:D11) -> 318 | F11: 46 | G11: 45 | H11: 45 | I11: 43 | J11: 54 | K11: 42 | L11: 43 | M11: =SUM(F11:L11) -> 318 | N11: 68 | O11: 250 | P11: =SUM(N11:O11) -> 318 | Q11: 309 | R11: 9 | S11: =SUM(Q11:R11) -> 318 | T11: 268 | U11: 185 | V11: 0 | W11: 0 | X11: 174 | Y11: 0 | Z11: 0 | AA11: =SUM(T11:Z11) -> 627 | AB11: 56 | AC11: 425 | AD11: 97 | AE11: 40 | AF11: 9 | AG11: =SUM(AB11:AF11) -> 627 | AH11: 521 | AI11: 106 | AJ11: =SUM(AH11:AI11) -> 627 | AK11: 485 | AL11: 142 | AM11: =SUM(AK11:AL11) -> 627 | AN11: 623 | AO11: 4 | AP11: =SUM(AN11:AO11) -> 627 | AQ11: 604 | AR11: 11 | AS11: 0 | AT11: 0 | AU11: 12 | AV11: =SUM(AQ11:AU11) -> 627 | AW11: =AU11 -> 12 | AX11: 576 | AY11: 39 | AZ11: =SUM(AW11:AY11) -> 627 | BA11: 308 | BB11: 2 | BC11: 1 | BD11: 1 | BE11: 0 | BF11: 5 | BG11: 0 | BH11: 1 | BI11: =SUM(BA11:BH11) -> 318 | BJ11: 0 | BK11: 31 | BL11: 58 | BM11: 5 | BN11: 82 | BO11: 0 | BP11: 142 | BQ11: =SUM(BJ11:BP11) -> 318 | BR11: 21 | BS11: 1 | BT11: 608 | BU11: =SUM(BR11:BT11) -> 630
A12: ذى القعدة | B12: 295 | C12: 9 | D12: 4 | E12: =SUM(B12:D12) -> 308 | F12: 41 | G12: 55 | H12: 35 | I12: 47 | J12: 41 | K12: 47 | L12: 42 | M12: =SUM(F12:L12) -> 308 | N12: 72 | O12: 236 | P12: =SUM(N12:O12) -> 308 | Q12: 298 | R12: 10 | S12: =SUM(Q12:R12) -> 308 | T12: 254 | U12: 178 | V12: 0 | W12: 0 | X12: 175 | Y12: 0 | Z12: 0 | AA12: =SUM(T12:Z12) -> 607 | AB12: 55 | AC12: 414 | AD12: 92 | AE12: 38 | AF12: 8 | AG12: =SUM(AB12:AF12) -> 607 | AH12: 473 | AI12: 134 | AJ12: =SUM(AH12:AI12) -> 607 | AK12: 466 | AL12: 141 | AM12: =SUM(AK12:AL12) -> 607 | AN12: 603 | AO12: 4 | AP12: =SUM(AN12:AO12) -> 607 | AQ12: 590 | AR12: 8 | AS12: 0 | AT12: 0 | AU12: 9 | AV12: =SUM(AQ12:AU12) -> 607 | AW12: =AU12 -> 9 | AX12: 566 | AY12: 32 | AZ12: =SUM(AW12:AY12) -> 607 | BA12: 297 | BB12: 3 | BC12: 5 | BD12: 0 | BE12: 0 | BF12: 3 | BG12: 0 | BH12: 0 | BI12: =SUM(BA12:BH12) -> 308 | BJ12: 0 | BK12: 31 | BL12: 56 | BM12: 0 | BN12: 88 | BO12: 0 | BP12: 133 | BQ12: =SUM(BJ12:BP12) -> 308 | BR12: 13 | BS12: 5 | BT12: 597 | BU12: =SUM(BR12:BT12) -> 615
A13: ذى الحجة | B13: 292 | C13: 18 | D13: 8 | E13: =SUM(B13:D13) -> 318 | F13: 56 | G13: 43 | H13: 42 | I13: 36 | J13: 41 | K13: 44 | L13: 56 | M13: =SUM(F13:L13) -> 318 | N13: 70 | O13: 248 | P13: =SUM(N13:O13) -> 318 | Q13: 308 | R13: 10 | S13: =SUM(Q13:R13) -> 318 | T13: 281 | U13: 178 | V13: 0 | W13: 0 | X13: 164 | Y13: 0 | Z13: 0 | AA13: =SUM(T13:Z13) -> 623 | AB13: 57 | AC13: 419 | AD13: 97 | AE13: 48 | AF13: 2 | AG13: =SUM(AB13:AF13) -> 623 | AH13: 506 | AI13: 117 | AJ13: =SUM(AH13:AI13) -> 623 | AK13: 479 | AL13: 144 | AM13: =SUM(AK13:AL13) -> 623 | AN13: 619 | AO13: 4 | AP13: =SUM(AN13:AO13) -> 623 | AQ13: 590 | AR13: 17 | AS13: 0 | AT13: 0 | AU13: 16 | AV13: =SUM(AQ13:AU13) -> 623 | AW13: =AU13 -> 16 | AX13: 571 | AY13: 36 | AZ13: =SUM(AW13:AY13) -> 623 | BA13: 300 | BB13: 10 | BC13: 3 | BD13: 0 | BE13: 0 | BF13: 5 | BG13: 0 | BH13: 0 | BI13: =SUM(BA13:BH13) -> 318 | BJ13: 0 | BK13: 29 | BL13: 62 | BM13: 0 | BN13: 85 | BO13: 0 | BP13: 142 | BQ13: =SUM(BJ13:BP13) -> 318 | BR13: 31 | BS13: 10 | BT13: 602 | BU13: =SUM(BR13:BT13) -> 643
A14: المجموع | B14: =SUM(B2:B13) -> 3526 | C14: =SUM(C2:C13) -> 215 | D14: =SUM(D2:D13) -> 54 | E14: =SUM(E2:E13) -> 3795 | F14: =SUM(F2:F13) -> 530 | G14: =SUM(G2:G13) -> 540 | H14: =SUM(H2:H13) -> 507 | I14: =SUM(I2:I13) -> 550 | ... BP14: =SUM(BP2:BP13) -> 1629 | BQ14: =SUM(BJ14:BP14) -> 3795 | BR14: =SUM(BR2:BR13) -> 346 | BS14: =SUM(BS2:BS13) -> 69 | BT14: =SUM(BT2:BT13) -> 7268 | BU14: =SUM(BU2:BU13) -> 7683

Sheet المجموع الكلي
A1: ا لـشـهـر | B1: 1436هـ | F1: إجمالى عــد د الحوادث موزعة حسب اليوم | N1: إجمالى عدد الحوادث موزعة حسب وقت الحادث | Q1: إجمالى عـدد الحوادث موزعة حسب مكان الحادث | T1: إجمالى عدد السيارات المشتركة في الحوادث حسب الطراز | AB1: العمر | AH1: الجنسية | AK1: الحالة الاجتماعية | AN1: الحالة التعليمية | AQ1: نوع الرخص | AU1: السائق لا يحمل رخصة قيادة | AV1: المجموع | AW1: السائق لا يحمل رخصة قيادة | AX1: سريان الرخصة | AZ1: المجموع | BA1: تصادم مع | BC1: دهس | BE1: حريق | BF1: انقلاب | BG1: خروج عن الطريق | BH1: اخرى | BI1: المجموع | BJ1: تحليل اســباب الحادث | BR1: الاشخاص المشمولين بالحوادث
A2: الشهر | B2: حادث تلفيات | C2: حادث اصابات | D2: حادث وفيات | E2: مجموع عدد الحوادث | F2: السبت | G2: الا حد | H2: الاثنين | I2: الثلاثاء | J2: الا ربعاء | K2: الخميس | L2: الجمعة | M2: مجموع عدد الحوادث لجميع الأيام | N2: نهارا | O2: ليلا | P2: مجموع عدد الحوادث حسب الوقت | Q2: داخل المدينة | R2: خارج المدينة | S2: مجموع عدد الحوادث حسب مكان الحادث | T2: صغيرة | U2: جيب | V2: حافلة | W2: ونيت | X2: نقل | Y2: وايت | Z2: اخرى | AA2: مجموع عدد السيارات المشتركة في الحوادث حسب الطراز | AB2: -18 | AC2: 18+ | AD2: 30+ | AE2: 40+ | AF2: 50+ | AG2: المجموع حسب العمر | AH2: سعودي | AI2: اجنبي | AJ2: المجموع حسب الجنسية | AK2: متزوج | AL2: اعزب | AM2: المجموع حسب الحالة الاجتماعية | AN2: متعلم | AO2: امى | AP2: المجموع حسب الحالة التعليمية | AQ2: نوع الرخصة خصوصى | AR2: نوع الرخصة عمومى | AS2: نوع الرخصة اليات | AT2: نوع الرخصة دراجة | AU2: السائق لا يحمل رخصة قيادة | AV2: المجموع | AW2: السائق لا يحمل رخصة قيادة | AX2: الرخصة سارية | AY2: الرخصة منتهية | AZ2: المجموع | BA2: تصادم مع سيارة | BB2: تصادم مع جسم ثابت | BC2: دهس مشاة | BD2: دهس حيوان | BE2: حريق | BF2: انقلاب | BG2: خروج عن الطريق | BH2: أخرى | BI2: المجموع | BJ2: توقف غير نظامى | BK2: دوران غير نظامى | BL2: تجاوز غير نظامى | BM2: عدم التقيد بالاشارة | BN2: السرعة الزائدة | BO2: السائق تحت تأثير مخدر | BP2: اخرى | BQ2: مجموع الحوادث حسب سبب الحادث | BR2: عدد المصابين | BS2: عدد المتوفين (القتلى) | BT2: سليم | BU2: مجموع الأشخاص المشمولين بالحوادث
